 Scheduler started
Scheduler started
Running job "enviar_mensagens_agendadas (trigger: interval[0:01:00], next run at: 2025-01-31 13:35:44 AEDT)" (scheduled at 2025-01-31 13:34:44.436381+11:00)
Running job "verificar_status (trigger: interval[0:01:00], next run at: 2025-01-31 13:35:44 AEDT)" (scheduled at 2025-01-31 13:34:44.436381+11:00)
Job "verificar_status (trigger: interval[0:01:00], next run at: 2025-01-31 13:35:44 AEDT)" raised an exception
Traceback (most recent call last):
  File "C:\Users\genti\OneDrive\Documentos\gestao_eventos\dhenv\Lib\site-packages\django\db\backends\base\base.py", line 275, in ensure_connection
    self.connect()
  File "C:\Users\genti\OneDrive\Documentos\gestao_eventos\dhenv\Lib\site-packages\django\utils\asyncio.py", line 26, in inner
    return func(*args, **kwargs)
           ^^^^^^^^^^^^^^^^^^^^^
  File "C:\Users\genti\OneDrive\Documentos\gestao_eventos\dhenv\Lib\site-packages\django\db\backends\base\base.py", line 256, in connect
    self.connection = self.get_new_connection(conn_params)
                      ^^^^^^^^^^^^^^^^^^^^^^^^^^^^^^^^^^^^
  File "C:\Users\genti\OneDrive\Documentos\gestao_eventos\dhenv\Lib\site-packages\django\utils\asyncio.py", line 26, in inner
    return func(*args, **kwargs)
           ^^^^^^^^^^^^^^^^^^^^^
  File "C:\Users\genti\OneDrive\Documentos\gestao_eventos\dhenv\Lib\site-packages\django\db\backends\postgresql\base.py", line 277, in get_new_connection
    connection = self.Database.connect(**conn_params)
                 ^^^^^^^^^^^^^^^^^^^^^^^^^^^^^^^^^^^^
  File "C:\Users\genti\OneDrive\Documentos\gestao_eventos\dhenv\Lib\site-packages\psycopg\connection.py", line 98, in connect
    attempts = conninfo_attempts(params)
               ^^^^^^^^^^^^^^^^^^^^^^^^^
  File "C:\Users\genti\OneDrive\Documentos\gestao_eventos\dhenv\Lib\site-packages\psycopg\_conninfo_attempts.py", line 50, in conninfo_attempts
    raise e.OperationalError(str(last_exc))
psycopg.OperationalError: [Errno 11001] getaddrinfo failed

The above exception was the direct cause of the following exception:

Traceback (most recent call last):
  File "C:\Users\genti\OneDrive\Documentos\gestao_eventos\dhenv\Lib\site-packages\apscheduler\executors\base.py", line 125, in run_job
    retval = job.func(*job.args, **job.kwargs)
             ^^^^^^^^^^^^^^^^^^^^^^^^^^^^^^^^^
  File "C:\Users\genti\OneDrive\Documentos\gestao_eventos\artistas\tasks.py", line 80, in verificar_status
    for artista in artistas:
  File "C:\Users\genti\OneDrive\Documentos\gestao_eventos\dhenv\Lib\site-packages\django\db\models\query.py", line 400, in __iter__
    self._fetch_all()
  File "C:\Users\genti\OneDrive\Documentos\gestao_eventos\dhenv\Lib\site-packages\django\db\models\query.py", line 1928, in _fetch_all
    self._result_cache = list(self._iterable_class(self))
                         ^^^^^^^^^^^^^^^^^^^^^^^^^^^^^^^^
  File "C:\Users\genti\OneDrive\Documentos\gestao_eventos\dhenv\Lib\site-packages\django\db\models\query.py", line 91, in __iter__
    results = compiler.execute_sql(
              ^^^^^^^^^^^^^^^^^^^^^
  File "C:\Users\genti\OneDrive\Documentos\gestao_eventos\dhenv\Lib\site-packages\django\db\models\sql\compiler.py", line 1560, in execute_sql
    cursor = self.connection.cursor()
             ^^^^^^^^^^^^^^^^^^^^^^^^
  File "C:\Users\genti\OneDrive\Documentos\gestao_eventos\dhenv\Lib\site-packages\django\utils\asyncio.py", line 26, in inner
    return func(*args, **kwargs)
           ^^^^^^^^^^^^^^^^^^^^^
  File "C:\Users\genti\OneDrive\Documentos\gestao_eventos\dhenv\Lib\site-packages\django\db\backends\base\base.py", line 316, in cursor
    return self._cursor()
           ^^^^^^^^^^^^^^
  File "C:\Users\genti\OneDrive\Documentos\gestao_eventos\dhenv\Lib\site-packages\django\db\backends\base\base.py", line 292, in _cursor
    self.ensure_connection()
  File "C:\Users\genti\OneDrive\Documentos\gestao_eventos\dhenv\Lib\site-packages\django\utils\asyncio.py", line 26, in inner
    return func(*args, **kwargs)
           ^^^^^^^^^^^^^^^^^^^^^
  File "C:\Users\genti\OneDrive\Documentos\gestao_eventos\dhenv\Lib\site-packages\django\db\backends\base\base.py", line 274, in ensure_connection
    with self.wrap_database_errors:
  File "C:\Users\genti\OneDrive\Documentos\gestao_eventos\dhenv\Lib\site-packages\django\db\utils.py", line 91, in __exit__
    raise dj_exc_value.with_traceback(traceback) from exc_value
  File "C:\Users\genti\OneDrive\Documentos\gestao_eventos\dhenv\Lib\site-packages\django\db\backends\base\base.py", line 275, in ensure_connection
    self.connect()
  File "C:\Users\genti\OneDrive\Documentos\gestao_eventos\dhenv\Lib\site-packages\django\utils\asyncio.py", line 26, in inner
    return func(*args, **kwargs)
           ^^^^^^^^^^^^^^^^^^^^^
  File "C:\Users\genti\OneDrive\Documentos\gestao_eventos\dhenv\Lib\site-packages\django\db\backends\base\base.py", line 256, in connect
    self.connection = self.get_new_connection(conn_params)
                      ^^^^^^^^^^^^^^^^^^^^^^^^^^^^^^^^^^^^
  File "C:\Users\genti\OneDrive\Documentos\gestao_eventos\dhenv\Lib\site-packages\django\utils\asyncio.py", line 26, in inner
    return func(*args, **kwargs)
           ^^^^^^^^^^^^^^^^^^^^^
  File "C:\Users\genti\OneDrive\Documentos\gestao_eventos\dhenv\Lib\site-packages\django\db\backends\postgresql\base.py", line 277, in get_new_connection
    connection = self.Database.connect(**conn_params)
                 ^^^^^^^^^^^^^^^^^^^^^^^^^^^^^^^^^^^^
  File "C:\Users\genti\OneDrive\Documentos\gestao_eventos\dhenv\Lib\site-packages\psycopg\connection.py", line 98, in connect
    attempts = conninfo_attempts(params)
               ^^^^^^^^^^^^^^^^^^^^^^^^^
  File "C:\Users\genti\OneDrive\Documentos\gestao_eventos\dhenv\Lib\site-packages\psycopg\_conninfo_attempts.py", line 50, in conninfo_attempts
    raise e.OperationalError(str(last_exc))
django.db.utils.OperationalError: [Errno 11001] getaddrinfo failed
Job "enviar_mensagens_agendadas (trigger: interval[0:01:00], next run at: 2025-01-31 13:35:44 AEDT)" raised an exception
Traceback (most recent call last):
  File "C:\Users\genti\OneDrive\Documentos\gestao_eventos\dhenv\Lib\site-packages\django\db\backends\base\base.py", line 275, in ensure_connection
    self.connect()
  File "C:\Users\genti\OneDrive\Documentos\gestao_eventos\dhenv\Lib\site-packages\django\utils\asyncio.py", line 26, in inner
    return func(*args, **kwargs)
           ^^^^^^^^^^^^^^^^^^^^^
  File "C:\Users\genti\OneDrive\Documentos\gestao_eventos\dhenv\Lib\site-packages\django\db\backends\base\base.py", line 256, in connect
    self.connection = self.get_new_connection(conn_params)
                      ^^^^^^^^^^^^^^^^^^^^^^^^^^^^^^^^^^^^
  File "C:\Users\genti\OneDrive\Documentos\gestao_eventos\dhenv\Lib\site-packages\django\utils\asyncio.py", line 26, in inner
    return func(*args, **kwargs)
           ^^^^^^^^^^^^^^^^^^^^^
  File "C:\Users\genti\OneDrive\Documentos\gestao_eventos\dhenv\Lib\site-packages\django\db\backends\postgresql\base.py", line 277, in get_new_connection
    connection = self.Database.connect(**conn_params)
                 ^^^^^^^^^^^^^^^^^^^^^^^^^^^^^^^^^^^^
  File "C:\Users\genti\OneDrive\Documentos\gestao_eventos\dhenv\Lib\site-packages\psycopg\connection.py", line 98, in connect
    attempts = conninfo_attempts(params)
               ^^^^^^^^^^^^^^^^^^^^^^^^^
  File "C:\Users\genti\OneDrive\Documentos\gestao_eventos\dhenv\Lib\site-packages\psycopg\_conninfo_attempts.py", line 50, in conninfo_attempts
    raise e.OperationalError(str(last_exc))
psycopg.OperationalError: [Errno 11001] getaddrinfo failed

The above exception was the direct cause of the following exception:

Traceback (most recent call last):
  File "C:\Users\genti\OneDrive\Documentos\gestao_eventos\dhenv\Lib\site-packages\apscheduler\executors\base.py", line 125, in run_job
    retval = job.func(*job.args, **job.kwargs)
             ^^^^^^^^^^^^^^^^^^^^^^^^^^^^^^^^^
  File "C:\Users\genti\OneDrive\Documentos\gestao_eventos\artistas\tasks.py", line 43, in enviar_mensagens_agendadas
    for artista in artistas:
  File "C:\Users\genti\OneDrive\Documentos\gestao_eventos\dhenv\Lib\site-packages\django\db\models\query.py", line 400, in __iter__
    self._fetch_all()
  File "C:\Users\genti\OneDrive\Documentos\gestao_eventos\dhenv\Lib\site-packages\django\db\models\query.py", line 1928, in _fetch_all
    self._result_cache = list(self._iterable_class(self))
                         ^^^^^^^^^^^^^^^^^^^^^^^^^^^^^^^^
  File "C:\Users\genti\OneDrive\Documentos\gestao_eventos\dhenv\Lib\site-packages\django\db\models\query.py", line 91, in __iter__
    results = compiler.execute_sql(
              ^^^^^^^^^^^^^^^^^^^^^
  File "C:\Users\genti\OneDrive\Documentos\gestao_eventos\dhenv\Lib\site-packages\django\db\models\sql\compiler.py", line 1560, in execute_sql
    cursor = self.connection.cursor()
             ^^^^^^^^^^^^^^^^^^^^^^^^
  File "C:\Users\genti\OneDrive\Documentos\gestao_eventos\dhenv\Lib\site-packages\django\utils\asyncio.py", line 26, in inner
    return func(*args, **kwargs)
           ^^^^^^^^^^^^^^^^^^^^^
  File "C:\Users\genti\OneDrive\Documentos\gestao_eventos\dhenv\Lib\site-packages\django\db\backends\base\base.py", line 316, in cursor
    return self._cursor()
           ^^^^^^^^^^^^^^
  File "C:\Users\genti\OneDrive\Documentos\gestao_eventos\dhenv\Lib\site-packages\django\db\backends\base\base.py", line 292, in _cursor
    self.ensure_connection()
  File "C:\Users\genti\OneDrive\Documentos\gestao_eventos\dhenv\Lib\site-packages\django\utils\asyncio.py", line 26, in inner
    return func(*args, **kwargs)
           ^^^^^^^^^^^^^^^^^^^^^
  File "C:\Users\genti\OneDrive\Documentos\gestao_eventos\dhenv\Lib\site-packages\django\db\backends\base\base.py", line 274, in ensure_connection
    with self.wrap_database_errors:
  File "C:\Users\genti\OneDrive\Documentos\gestao_eventos\dhenv\Lib\site-packages\django\db\utils.py", line 91, in __exit__
    raise dj_exc_value.with_traceback(traceback) from exc_value
  File "C:\Users\genti\OneDrive\Documentos\gestao_eventos\dhenv\Lib\site-packages\django\db\backends\base\base.py", line 275, in ensure_connection
    self.connect()
  File "C:\Users\genti\OneDrive\Documentos\gestao_eventos\dhenv\Lib\site-packages\django\utils\asyncio.py", line 26, in inner
    return func(*args, **kwargs)
           ^^^^^^^^^^^^^^^^^^^^^
  File "C:\Users\genti\OneDrive\Documentos\gestao_eventos\dhenv\Lib\site-packages\django\db\backends\base\base.py", line 256, in connect
    self.connection = self.get_new_connection(conn_params)
                      ^^^^^^^^^^^^^^^^^^^^^^^^^^^^^^^^^^^^
  File "C:\Users\genti\OneDrive\Documentos\gestao_eventos\dhenv\Lib\site-packages\django\utils\asyncio.py", line 26, in inner
    return func(*args, **kwargs)
           ^^^^^^^^^^^^^^^^^^^^^
  File "C:\Users\genti\OneDrive\Documentos\gestao_eventos\dhenv\Lib\site-packages\django\db\backends\postgresql\base.py", line 277, in get_new_connection
    connection = self.Database.connect(**conn_params)
                 ^^^^^^^^^^^^^^^^^^^^^^^^^^^^^^^^^^^^
  File "C:\Users\genti\OneDrive\Documentos\gestao_eventos\dhenv\Lib\site-packages\psycopg\connection.py", line 98, in connect
    attempts = conninfo_attempts(params)
               ^^^^^^^^^^^^^^^^^^^^^^^^^
  File "C:\Users\genti\OneDrive\Documentos\gestao_eventos\dhenv\Lib\site-packages\psycopg\_conninfo_attempts.py", line 50, in conninfo_attempts
    raise e.OperationalError(str(last_exc))
django.db.utils.OperationalError: [Errno 11001] getaddrinfo failed
Running job "enviar_mensagens_agendadas (trigger: interval[0:01:00], next run at: 2025-01-31 13:36:44 AEDT)" (scheduled at 2025-01-31 13:35:44.436381+11:00)
Running job "verificar_status (trigger: interval[0:01:00], next run at: 2025-01-31 13:36:44 AEDT)" (scheduled at 2025-01-31 13:35:44.436381+11:00)
Job "verificar_status (trigger: interval[0:01:00], next run at: 2025-01-31 13:36:44 AEDT)" raised an exception
Traceback (most recent call last):
  File "C:\Users\genti\OneDrive\Documentos\gestao_eventos\dhenv\Lib\site-packages\django\db\backends\base\base.py", line 275, in ensure_connection
    self.connect()
  File "C:\Users\genti\OneDrive\Documentos\gestao_eventos\dhenv\Lib\site-packages\django\utils\asyncio.py", line 26, in inner
    return func(*args, **kwargs)
           ^^^^^^^^^^^^^^^^^^^^^
  File "C:\Users\genti\OneDrive\Documentos\gestao_eventos\dhenv\Lib\site-packages\django\db\backends\base\base.py", line 256, in connect
    self.connection = self.get_new_connection(conn_params)
                      ^^^^^^^^^^^^^^^^^^^^^^^^^^^^^^^^^^^^
  File "C:\Users\genti\OneDrive\Documentos\gestao_eventos\dhenv\Lib\site-packages\django\utils\asyncio.py", line 26, in inner
    return func(*args, **kwargs)
           ^^^^^^^^^^^^^^^^^^^^^
  File "C:\Users\genti\OneDrive\Documentos\gestao_eventos\dhenv\Lib\site-packages\django\db\backends\postgresql\base.py", line 277, in get_new_connection
    connection = self.Database.connect(**conn_params)
                 ^^^^^^^^^^^^^^^^^^^^^^^^^^^^^^^^^^^^
  File "C:\Users\genti\OneDrive\Documentos\gestao_eventos\dhenv\Lib\site-packages\psycopg\connection.py", line 98, in connect
    attempts = conninfo_attempts(params)
               ^^^^^^^^^^^^^^^^^^^^^^^^^
  File "C:\Users\genti\OneDrive\Documentos\gestao_eventos\dhenv\Lib\site-packages\psycopg\_conninfo_attempts.py", line 50, in conninfo_attempts
    raise e.OperationalError(str(last_exc))
psycopg.OperationalError: [Errno 11001] getaddrinfo failed

The above exception was the direct cause of the following exception:

Traceback (most recent call last):
  File "C:\Users\genti\OneDrive\Documentos\gestao_eventos\dhenv\Lib\site-packages\apscheduler\executors\base.py", line 125, in run_job
    retval = job.func(*job.args, **job.kwargs)
             ^^^^^^^^^^^^^^^^^^^^^^^^^^^^^^^^^
  File "C:\Users\genti\OneDrive\Documentos\gestao_eventos\artistas\tasks.py", line 80, in verificar_status
    for artista in artistas:
  File "C:\Users\genti\OneDrive\Documentos\gestao_eventos\dhenv\Lib\site-packages\django\db\models\query.py", line 400, in __iter__
    self._fetch_all()
  File "C:\Users\genti\OneDrive\Documentos\gestao_eventos\dhenv\Lib\site-packages\django\db\models\query.py", line 1928, in _fetch_all
    self._result_cache = list(self._iterable_class(self))
                         ^^^^^^^^^^^^^^^^^^^^^^^^^^^^^^^^
  File "C:\Users\genti\OneDrive\Documentos\gestao_eventos\dhenv\Lib\site-packages\django\db\models\query.py", line 91, in __iter__
    results = compiler.execute_sql(
              ^^^^^^^^^^^^^^^^^^^^^
  File "C:\Users\genti\OneDrive\Documentos\gestao_eventos\dhenv\Lib\site-packages\django\db\models\sql\compiler.py", line 1560, in execute_sql
    cursor = self.connection.cursor()
             ^^^^^^^^^^^^^^^^^^^^^^^^
  File "C:\Users\genti\OneDrive\Documentos\gestao_eventos\dhenv\Lib\site-packages\django\utils\asyncio.py", line 26, in inner
    return func(*args, **kwargs)
           ^^^^^^^^^^^^^^^^^^^^^
  File "C:\Users\genti\OneDrive\Documentos\gestao_eventos\dhenv\Lib\site-packages\django\db\backends\base\base.py", line 316, in cursor
    return self._cursor()
           ^^^^^^^^^^^^^^
  File "C:\Users\genti\OneDrive\Documentos\gestao_eventos\dhenv\Lib\site-packages\django\db\backends\base\base.py", line 292, in _cursor
    self.ensure_connection()
  File "C:\Users\genti\OneDrive\Documentos\gestao_eventos\dhenv\Lib\site-packages\django\utils\asyncio.py", line 26, in inner
    return func(*args, **kwargs)
           ^^^^^^^^^^^^^^^^^^^^^
  File "C:\Users\genti\OneDrive\Documentos\gestao_eventos\dhenv\Lib\site-packages\django\db\backends\base\base.py", line 274, in ensure_connection
    with self.wrap_database_errors:
  File "C:\Users\genti\OneDrive\Documentos\gestao_eventos\dhenv\Lib\site-packages\django\db\utils.py", line 91, in __exit__
    raise dj_exc_value.with_traceback(traceback) from exc_value
  File "C:\Users\genti\OneDrive\Documentos\gestao_eventos\dhenv\Lib\site-packages\django\db\backends\base\base.py", line 275, in ensure_connection
    self.connect()
  File "C:\Users\genti\OneDrive\Documentos\gestao_eventos\dhenv\Lib\site-packages\django\utils\asyncio.py", line 26, in inner
    return func(*args, **kwargs)
           ^^^^^^^^^^^^^^^^^^^^^
  File "C:\Users\genti\OneDrive\Documentos\gestao_eventos\dhenv\Lib\site-packages\django\db\backends\base\base.py", line 256, in connect
    self.connection = self.get_new_connection(conn_params)
                      ^^^^^^^^^^^^^^^^^^^^^^^^^^^^^^^^^^^^
  File "C:\Users\genti\OneDrive\Documentos\gestao_eventos\dhenv\Lib\site-packages\django\utils\asyncio.py", line 26, in inner
    return func(*args, **kwargs)
           ^^^^^^^^^^^^^^^^^^^^^
  File "C:\Users\genti\OneDrive\Documentos\gestao_eventos\dhenv\Lib\site-packages\django\db\backends\postgresql\base.py", line 277, in get_new_connection
    connection = self.Database.connect(**conn_params)
                 ^^^^^^^^^^^^^^^^^^^^^^^^^^^^^^^^^^^^
  File "C:\Users\genti\OneDrive\Documentos\gestao_eventos\dhenv\Lib\site-packages\psycopg\connection.py", line 98, in connect
    attempts = conninfo_attempts(params)
               ^^^^^^^^^^^^^^^^^^^^^^^^^
  File "C:\Users\genti\OneDrive\Documentos\gestao_eventos\dhenv\Lib\site-packages\psycopg\_conninfo_attempts.py", line 50, in conninfo_attempts
    raise e.OperationalError(str(last_exc))
django.db.utils.OperationalError: [Errno 11001] getaddrinfo failed
Job "enviar_mensagens_agendadas (trigger: interval[0:01:00], next run at: 2025-01-31 13:36:44 AEDT)" raised an exception
Traceback (most recent call last):
  File "C:\Users\genti\OneDrive\Documentos\gestao_eventos\dhenv\Lib\site-packages\django\db\backends\base\base.py", line 275, in ensure_connection
    self.connect()
  File "C:\Users\genti\OneDrive\Documentos\gestao_eventos\dhenv\Lib\site-packages\django\utils\asyncio.py", line 26, in inner
    return func(*args, **kwargs)
           ^^^^^^^^^^^^^^^^^^^^^
  File "C:\Users\genti\OneDrive\Documentos\gestao_eventos\dhenv\Lib\site-packages\django\db\backends\base\base.py", line 256, in connect
    self.connection = self.get_new_connection(conn_params)
                      ^^^^^^^^^^^^^^^^^^^^^^^^^^^^^^^^^^^^
  File "C:\Users\genti\OneDrive\Documentos\gestao_eventos\dhenv\Lib\site-packages\django\utils\asyncio.py", line 26, in inner
    return func(*args, **kwargs)
           ^^^^^^^^^^^^^^^^^^^^^
  File "C:\Users\genti\OneDrive\Documentos\gestao_eventos\dhenv\Lib\site-packages\django\db\backends\postgresql\base.py", line 277, in get_new_connection
    connection = self.Database.connect(**conn_params)
                 ^^^^^^^^^^^^^^^^^^^^^^^^^^^^^^^^^^^^
  File "C:\Users\genti\OneDrive\Documentos\gestao_eventos\dhenv\Lib\site-packages\psycopg\connection.py", line 98, in connect
    attempts = conninfo_attempts(params)
               ^^^^^^^^^^^^^^^^^^^^^^^^^
  File "C:\Users\genti\OneDrive\Documentos\gestao_eventos\dhenv\Lib\site-packages\psycopg\_conninfo_attempts.py", line 50, in conninfo_attempts
    raise e.OperationalError(str(last_exc))
psycopg.OperationalError: [Errno 11001] getaddrinfo failed

The above exception was the direct cause of the following exception:

Traceback (most recent call last):
  File "C:\Users\genti\OneDrive\Documentos\gestao_eventos\dhenv\Lib\site-packages\apscheduler\executors\base.py", line 125, in run_job
    retval = job.func(*job.args, **job.kwargs)
             ^^^^^^^^^^^^^^^^^^^^^^^^^^^^^^^^^
  File "C:\Users\genti\OneDrive\Documentos\gestao_eventos\artistas\tasks.py", line 43, in enviar_mensagens_agendadas
    for artista in artistas:
  File "C:\Users\genti\OneDrive\Documentos\gestao_eventos\dhenv\Lib\site-packages\django\db\models\query.py", line 400, in __iter__
    self._fetch_all()
  File "C:\Users\genti\OneDrive\Documentos\gestao_eventos\dhenv\Lib\site-packages\django\db\models\query.py", line 1928, in _fetch_all
    self._result_cache = list(self._iterable_class(self))
                         ^^^^^^^^^^^^^^^^^^^^^^^^^^^^^^^^
  File "C:\Users\genti\OneDrive\Documentos\gestao_eventos\dhenv\Lib\site-packages\django\db\models\query.py", line 91, in __iter__
    results = compiler.execute_sql(
              ^^^^^^^^^^^^^^^^^^^^^
  File "C:\Users\genti\OneDrive\Documentos\gestao_eventos\dhenv\Lib\site-packages\django\db\models\sql\compiler.py", line 1560, in execute_sql
    cursor = self.connection.cursor()
             ^^^^^^^^^^^^^^^^^^^^^^^^
  File "C:\Users\genti\OneDrive\Documentos\gestao_eventos\dhenv\Lib\site-packages\django\utils\asyncio.py", line 26, in inner
    return func(*args, **kwargs)
           ^^^^^^^^^^^^^^^^^^^^^
  File "C:\Users\genti\OneDrive\Documentos\gestao_eventos\dhenv\Lib\site-packages\django\db\backends\base\base.py", line 316, in cursor
    return self._cursor()
           ^^^^^^^^^^^^^^
  File "C:\Users\genti\OneDrive\Documentos\gestao_eventos\dhenv\Lib\site-packages\django\db\backends\base\base.py", line 292, in _cursor
    self.ensure_connection()
  File "C:\Users\genti\OneDrive\Documentos\gestao_eventos\dhenv\Lib\site-packages\django\utils\asyncio.py", line 26, in inner
    return func(*args, **kwargs)
           ^^^^^^^^^^^^^^^^^^^^^
  File "C:\Users\genti\OneDrive\Documentos\gestao_eventos\dhenv\Lib\site-packages\django\db\backends\base\base.py", line 274, in ensure_connection
    with self.wrap_database_errors:
  File "C:\Users\genti\OneDrive\Documentos\gestao_eventos\dhenv\Lib\site-packages\django\db\utils.py", line 91, in __exit__
    raise dj_exc_value.with_traceback(traceback) from exc_value
  File "C:\Users\genti\OneDrive\Documentos\gestao_eventos\dhenv\Lib\site-packages\django\db\backends\base\base.py", line 275, in ensure_connection
    self.connect()
  File "C:\Users\genti\OneDrive\Documentos\gestao_eventos\dhenv\Lib\site-packages\django\utils\asyncio.py", line 26, in inner
    return func(*args, **kwargs)
           ^^^^^^^^^^^^^^^^^^^^^
  File "C:\Users\genti\OneDrive\Documentos\gestao_eventos\dhenv\Lib\site-packages\django\db\backends\base\base.py", line 256, in connect
    self.connection = self.get_new_connection(conn_params)
                      ^^^^^^^^^^^^^^^^^^^^^^^^^^^^^^^^^^^^
  File "C:\Users\genti\OneDrive\Documentos\gestao_eventos\dhenv\Lib\site-packages\django\utils\asyncio.py", line 26, in inner
    return func(*args, **kwargs)
           ^^^^^^^^^^^^^^^^^^^^^
  File "C:\Users\genti\OneDrive\Documentos\gestao_eventos\dhenv\Lib\site-packages\django\db\backends\postgresql\base.py", line 277, in get_new_connection
    connection = self.Database.connect(**conn_params)
                 ^^^^^^^^^^^^^^^^^^^^^^^^^^^^^^^^^^^^
  File "C:\Users\genti\OneDrive\Documentos\gestao_eventos\dhenv\Lib\site-packages\psycopg\connection.py", line 98, in connect
    attempts = conninfo_attempts(params)
               ^^^^^^^^^^^^^^^^^^^^^^^^^
  File "C:\Users\genti\OneDrive\Documentos\gestao_eventos\dhenv\Lib\site-packages\psycopg\_conninfo_attempts.py", line 50, in conninfo_attempts
    raise e.OperationalError(str(last_exc))
django.db.utils.OperationalError: [Errno 11001] getaddrinfo failed
Running job "enviar_mensagens_agendadas (trigger: interval[0:01:00], next run at: 2025-01-31 13:37:44 AEDT)" (scheduled at 2025-01-31 13:36:44.436381+11:00)
Running job "verificar_status (trigger: interval[0:01:00], next run at: 2025-01-31 13:37:44 AEDT)" (scheduled at 2025-01-31 13:36:44.436381+11:00)
Job "enviar_mensagens_agendadas (trigger: interval[0:01:00], next run at: 2025-01-31 13:37:44 AEDT)" raised an exception
Traceback (most recent call last):
  File "C:\Users\genti\OneDrive\Documentos\gestao_eventos\dhenv\Lib\site-packages\django\db\backends\base\base.py", line 275, in ensure_connection
    self.connect()
  File "C:\Users\genti\OneDrive\Documentos\gestao_eventos\dhenv\Lib\site-packages\django\utils\asyncio.py", line 26, in inner
    return func(*args, **kwargs)
           ^^^^^^^^^^^^^^^^^^^^^
  File "C:\Users\genti\OneDrive\Documentos\gestao_eventos\dhenv\Lib\site-packages\django\db\backends\base\base.py", line 256, in connect
    self.connection = self.get_new_connection(conn_params)
                      ^^^^^^^^^^^^^^^^^^^^^^^^^^^^^^^^^^^^
  File "C:\Users\genti\OneDrive\Documentos\gestao_eventos\dhenv\Lib\site-packages\django\utils\asyncio.py", line 26, in inner
    return func(*args, **kwargs)
           ^^^^^^^^^^^^^^^^^^^^^
  File "C:\Users\genti\OneDrive\Documentos\gestao_eventos\dhenv\Lib\site-packages\django\db\backends\postgresql\base.py", line 277, in get_new_connection
    connection = self.Database.connect(**conn_params)
                 ^^^^^^^^^^^^^^^^^^^^^^^^^^^^^^^^^^^^
  File "C:\Users\genti\OneDrive\Documentos\gestao_eventos\dhenv\Lib\site-packages\psycopg\connection.py", line 98, in connect
    attempts = conninfo_attempts(params)
               ^^^^^^^^^^^^^^^^^^^^^^^^^
  File "C:\Users\genti\OneDrive\Documentos\gestao_eventos\dhenv\Lib\site-packages\psycopg\_conninfo_attempts.py", line 50, in conninfo_attempts
    raise e.OperationalError(str(last_exc))
psycopg.OperationalError: [Errno 11001] getaddrinfo failed

The above exception was the direct cause of the following exception:

Traceback (most recent call last):
  File "C:\Users\genti\OneDrive\Documentos\gestao_eventos\dhenv\Lib\site-packages\apscheduler\executors\base.py", line 125, in run_job
    retval = job.func(*job.args, **job.kwargs)
             ^^^^^^^^^^^^^^^^^^^^^^^^^^^^^^^^^
  File "C:\Users\genti\OneDrive\Documentos\gestao_eventos\artistas\tasks.py", line 43, in enviar_mensagens_agendadas
    for artista in artistas:
  File "C:\Users\genti\OneDrive\Documentos\gestao_eventos\dhenv\Lib\site-packages\django\db\models\query.py", line 400, in __iter__
    self._fetch_all()
  File "C:\Users\genti\OneDrive\Documentos\gestao_eventos\dhenv\Lib\site-packages\django\db\models\query.py", line 1928, in _fetch_all
    self._result_cache = list(self._iterable_class(self))
                         ^^^^^^^^^^^^^^^^^^^^^^^^^^^^^^^^
  File "C:\Users\genti\OneDrive\Documentos\gestao_eventos\dhenv\Lib\site-packages\django\db\models\query.py", line 91, in __iter__
    results = compiler.execute_sql(
              ^^^^^^^^^^^^^^^^^^^^^
  File "C:\Users\genti\OneDrive\Documentos\gestao_eventos\dhenv\Lib\site-packages\django\db\models\sql\compiler.py", line 1560, in execute_sql
    cursor = self.connection.cursor()
             ^^^^^^^^^^^^^^^^^^^^^^^^
  File "C:\Users\genti\OneDrive\Documentos\gestao_eventos\dhenv\Lib\site-packages\django\utils\asyncio.py", line 26, in inner
    return func(*args, **kwargs)
           ^^^^^^^^^^^^^^^^^^^^^
  File "C:\Users\genti\OneDrive\Documentos\gestao_eventos\dhenv\Lib\site-packages\django\db\backends\base\base.py", line 316, in cursor
    return self._cursor()
           ^^^^^^^^^^^^^^
  File "C:\Users\genti\OneDrive\Documentos\gestao_eventos\dhenv\Lib\site-packages\django\db\backends\base\base.py", line 292, in _cursor
    self.ensure_connection()
  File "C:\Users\genti\OneDrive\Documentos\gestao_eventos\dhenv\Lib\site-packages\django\utils\asyncio.py", line 26, in inner
    return func(*args, **kwargs)
           ^^^^^^^^^^^^^^^^^^^^^
  File "C:\Users\genti\OneDrive\Documentos\gestao_eventos\dhenv\Lib\site-packages\django\db\backends\base\base.py", line 274, in ensure_connection
    with self.wrap_database_errors:
  File "C:\Users\genti\OneDrive\Documentos\gestao_eventos\dhenv\Lib\site-packages\django\db\utils.py", line 91, in __exit__
    raise dj_exc_value.with_traceback(traceback) from exc_value
  File "C:\Users\genti\OneDrive\Documentos\gestao_eventos\dhenv\Lib\site-packages\django\db\backends\base\base.py", line 275, in ensure_connection
    self.connect()
  File "C:\Users\genti\OneDrive\Documentos\gestao_eventos\dhenv\Lib\site-packages\django\utils\asyncio.py", line 26, in inner
    return func(*args, **kwargs)
           ^^^^^^^^^^^^^^^^^^^^^
  File "C:\Users\genti\OneDrive\Documentos\gestao_eventos\dhenv\Lib\site-packages\django\db\backends\base\base.py", line 256, in connect
    self.connection = self.get_new_connection(conn_params)
                      ^^^^^^^^^^^^^^^^^^^^^^^^^^^^^^^^^^^^
  File "C:\Users\genti\OneDrive\Documentos\gestao_eventos\dhenv\Lib\site-packages\django\utils\asyncio.py", line 26, in inner
    return func(*args, **kwargs)
           ^^^^^^^^^^^^^^^^^^^^^
  File "C:\Users\genti\OneDrive\Documentos\gestao_eventos\dhenv\Lib\site-packages\django\db\backends\postgresql\base.py", line 277, in get_new_connection
    connection = self.Database.connect(**conn_params)
                 ^^^^^^^^^^^^^^^^^^^^^^^^^^^^^^^^^^^^
  File "C:\Users\genti\OneDrive\Documentos\gestao_eventos\dhenv\Lib\site-packages\psycopg\connection.py", line 98, in connect
    attempts = conninfo_attempts(params)
               ^^^^^^^^^^^^^^^^^^^^^^^^^
  File "C:\Users\genti\OneDrive\Documentos\gestao_eventos\dhenv\Lib\site-packages\psycopg\_conninfo_attempts.py", line 50, in conninfo_attempts
    raise e.OperationalError(str(last_exc))
django.db.utils.OperationalError: [Errno 11001] getaddrinfo failed
Job "verificar_status (trigger: interval[0:01:00], next run at: 2025-01-31 13:37:44 AEDT)" raised an exception
Traceback (most recent call last):
  File "C:\Users\genti\OneDrive\Documentos\gestao_eventos\dhenv\Lib\site-packages\django\db\backends\base\base.py", line 275, in ensure_connection
    self.connect()
  File "C:\Users\genti\OneDrive\Documentos\gestao_eventos\dhenv\Lib\site-packages\django\utils\asyncio.py", line 26, in inner
    return func(*args, **kwargs)
           ^^^^^^^^^^^^^^^^^^^^^
  File "C:\Users\genti\OneDrive\Documentos\gestao_eventos\dhenv\Lib\site-packages\django\db\backends\base\base.py", line 256, in connect
    self.connection = self.get_new_connection(conn_params)
                      ^^^^^^^^^^^^^^^^^^^^^^^^^^^^^^^^^^^^
  File "C:\Users\genti\OneDrive\Documentos\gestao_eventos\dhenv\Lib\site-packages\django\utils\asyncio.py", line 26, in inner
    return func(*args, **kwargs)
           ^^^^^^^^^^^^^^^^^^^^^
  File "C:\Users\genti\OneDrive\Documentos\gestao_eventos\dhenv\Lib\site-packages\django\db\backends\postgresql\base.py", line 277, in get_new_connection
    connection = self.Database.connect(**conn_params)
                 ^^^^^^^^^^^^^^^^^^^^^^^^^^^^^^^^^^^^
  File "C:\Users\genti\OneDrive\Documentos\gestao_eventos\dhenv\Lib\site-packages\psycopg\connection.py", line 98, in connect
    attempts = conninfo_attempts(params)
               ^^^^^^^^^^^^^^^^^^^^^^^^^
  File "C:\Users\genti\OneDrive\Documentos\gestao_eventos\dhenv\Lib\site-packages\psycopg\_conninfo_attempts.py", line 50, in conninfo_attempts
    raise e.OperationalError(str(last_exc))
psycopg.OperationalError: [Errno 11001] getaddrinfo failed

The above exception was the direct cause of the following exception:

Traceback (most recent call last):
  File "C:\Users\genti\OneDrive\Documentos\gestao_eventos\dhenv\Lib\site-packages\apscheduler\executors\base.py", line 125, in run_job
    retval = job.func(*job.args, **job.kwargs)
             ^^^^^^^^^^^^^^^^^^^^^^^^^^^^^^^^^
  File "C:\Users\genti\OneDrive\Documentos\gestao_eventos\artistas\tasks.py", line 80, in verificar_status
    for artista in artistas:
  File "C:\Users\genti\OneDrive\Documentos\gestao_eventos\dhenv\Lib\site-packages\django\db\models\query.py", line 400, in __iter__
    self._fetch_all()
  File "C:\Users\genti\OneDrive\Documentos\gestao_eventos\dhenv\Lib\site-packages\django\db\models\query.py", line 1928, in _fetch_all
    self._result_cache = list(self._iterable_class(self))
                         ^^^^^^^^^^^^^^^^^^^^^^^^^^^^^^^^
  File "C:\Users\genti\OneDrive\Documentos\gestao_eventos\dhenv\Lib\site-packages\django\db\models\query.py", line 91, in __iter__
    results = compiler.execute_sql(
              ^^^^^^^^^^^^^^^^^^^^^
  File "C:\Users\genti\OneDrive\Documentos\gestao_eventos\dhenv\Lib\site-packages\django\db\models\sql\compiler.py", line 1560, in execute_sql
    cursor = self.connection.cursor()
             ^^^^^^^^^^^^^^^^^^^^^^^^
  File "C:\Users\genti\OneDrive\Documentos\gestao_eventos\dhenv\Lib\site-packages\django\utils\asyncio.py", line 26, in inner
    return func(*args, **kwargs)
           ^^^^^^^^^^^^^^^^^^^^^
  File "C:\Users\genti\OneDrive\Documentos\gestao_eventos\dhenv\Lib\site-packages\django\db\backends\base\base.py", line 316, in cursor
    return self._cursor()
           ^^^^^^^^^^^^^^
  File "C:\Users\genti\OneDrive\Documentos\gestao_eventos\dhenv\Lib\site-packages\django\db\backends\base\base.py", line 292, in _cursor
    self.ensure_connection()
  File "C:\Users\genti\OneDrive\Documentos\gestao_eventos\dhenv\Lib\site-packages\django\utils\asyncio.py", line 26, in inner
    return func(*args, **kwargs)
           ^^^^^^^^^^^^^^^^^^^^^
  File "C:\Users\genti\OneDrive\Documentos\gestao_eventos\dhenv\Lib\site-packages\django\db\backends\base\base.py", line 274, in ensure_connection
    with self.wrap_database_errors:
  File "C:\Users\genti\OneDrive\Documentos\gestao_eventos\dhenv\Lib\site-packages\django\db\utils.py", line 91, in __exit__
    raise dj_exc_value.with_traceback(traceback) from exc_value
  File "C:\Users\genti\OneDrive\Documentos\gestao_eventos\dhenv\Lib\site-packages\django\db\backends\base\base.py", line 275, in ensure_connection
    self.connect()
  File "C:\Users\genti\OneDrive\Documentos\gestao_eventos\dhenv\Lib\site-packages\django\utils\asyncio.py", line 26, in inner
    return func(*args, **kwargs)
           ^^^^^^^^^^^^^^^^^^^^^
  File "C:\Users\genti\OneDrive\Documentos\gestao_eventos\dhenv\Lib\site-packages\django\db\backends\base\base.py", line 256, in connect
    self.connection = self.get_new_connection(conn_params)
                      ^^^^^^^^^^^^^^^^^^^^^^^^^^^^^^^^^^^^
  File "C:\Users\genti\OneDrive\Documentos\gestao_eventos\dhenv\Lib\site-packages\django\utils\asyncio.py", line 26, in inner
    return func(*args, **kwargs)
           ^^^^^^^^^^^^^^^^^^^^^
  File "C:\Users\genti\OneDrive\Documentos\gestao_eventos\dhenv\Lib\site-packages\django\db\backends\postgresql\base.py", line 277, in get_new_connection
    connection = self.Database.connect(**conn_params)
                 ^^^^^^^^^^^^^^^^^^^^^^^^^^^^^^^^^^^^
  File "C:\Users\genti\OneDrive\Documentos\gestao_eventos\dhenv\Lib\site-packages\psycopg\connection.py", line 98, in connect
    attempts = conninfo_attempts(params)
               ^^^^^^^^^^^^^^^^^^^^^^^^^
  File "C:\Users\genti\OneDrive\Documentos\gestao_eventos\dhenv\Lib\site-packages\psycopg\_conninfo_attempts.py", line 50, in conninfo_attempts
    raise e.OperationalError(str(last_exc))
django.db.utils.OperationalError: [Errno 11001] getaddrinfo failed
Running job "enviar_mensagens_agendadas (trigger: interval[0:01:00], next run at: 2025-01-31 13:38:44 AEDT)" (scheduled at 2025-01-31 13:37:44.436381+11:00)
Running job "verificar_status (trigger: interval[0:01:00], next run at: 2025-01-31 13:38:44 AEDT)" (scheduled at 2025-01-31 13:37:44.436381+11:00)
Job "verificar_status (trigger: interval[0:01:00], next run at: 2025-01-31 13:38:44 AEDT)" raised an exception
Traceback (most recent call last):
  File "C:\Users\genti\OneDrive\Documentos\gestao_eventos\dhenv\Lib\site-packages\django\db\backends\base\base.py", line 275, in ensure_connection
    self.connect()
  File "C:\Users\genti\OneDrive\Documentos\gestao_eventos\dhenv\Lib\site-packages\django\utils\asyncio.py", line 26, in inner
    return func(*args, **kwargs)
           ^^^^^^^^^^^^^^^^^^^^^
  File "C:\Users\genti\OneDrive\Documentos\gestao_eventos\dhenv\Lib\site-packages\django\db\backends\base\base.py", line 256, in connect
    self.connection = self.get_new_connection(conn_params)
                      ^^^^^^^^^^^^^^^^^^^^^^^^^^^^^^^^^^^^
  File "C:\Users\genti\OneDrive\Documentos\gestao_eventos\dhenv\Lib\site-packages\django\utils\asyncio.py", line 26, in inner
    return func(*args, **kwargs)
           ^^^^^^^^^^^^^^^^^^^^^
  File "C:\Users\genti\OneDrive\Documentos\gestao_eventos\dhenv\Lib\site-packages\django\db\backends\postgresql\base.py", line 277, in get_new_connection
    connection = self.Database.connect(**conn_params)
                 ^^^^^^^^^^^^^^^^^^^^^^^^^^^^^^^^^^^^
  File "C:\Users\genti\OneDrive\Documentos\gestao_eventos\dhenv\Lib\site-packages\psycopg\connection.py", line 98, in connect
    attempts = conninfo_attempts(params)
               ^^^^^^^^^^^^^^^^^^^^^^^^^
  File "C:\Users\genti\OneDrive\Documentos\gestao_eventos\dhenv\Lib\site-packages\psycopg\_conninfo_attempts.py", line 50, in conninfo_attempts
    raise e.OperationalError(str(last_exc))
psycopg.OperationalError: [Errno 11001] getaddrinfo failed

The above exception was the direct cause of the following exception:

Traceback (most recent call last):
  File "C:\Users\genti\OneDrive\Documentos\gestao_eventos\dhenv\Lib\site-packages\apscheduler\executors\base.py", line 125, in run_job
    retval = job.func(*job.args, **job.kwargs)
             ^^^^^^^^^^^^^^^^^^^^^^^^^^^^^^^^^
  File "C:\Users\genti\OneDrive\Documentos\gestao_eventos\artistas\tasks.py", line 80, in verificar_status
    for artista in artistas:
  File "C:\Users\genti\OneDrive\Documentos\gestao_eventos\dhenv\Lib\site-packages\django\db\models\query.py", line 400, in __iter__
    self._fetch_all()
  File "C:\Users\genti\OneDrive\Documentos\gestao_eventos\dhenv\Lib\site-packages\django\db\models\query.py", line 1928, in _fetch_all
    self._result_cache = list(self._iterable_class(self))
                         ^^^^^^^^^^^^^^^^^^^^^^^^^^^^^^^^
  File "C:\Users\genti\OneDrive\Documentos\gestao_eventos\dhenv\Lib\site-packages\django\db\models\query.py", line 91, in __iter__
    results = compiler.execute_sql(
              ^^^^^^^^^^^^^^^^^^^^^
  File "C:\Users\genti\OneDrive\Documentos\gestao_eventos\dhenv\Lib\site-packages\django\db\models\sql\compiler.py", line 1560, in execute_sql
    cursor = self.connection.cursor()
             ^^^^^^^^^^^^^^^^^^^^^^^^
  File "C:\Users\genti\OneDrive\Documentos\gestao_eventos\dhenv\Lib\site-packages\django\utils\asyncio.py", line 26, in inner
    return func(*args, **kwargs)
           ^^^^^^^^^^^^^^^^^^^^^
  File "C:\Users\genti\OneDrive\Documentos\gestao_eventos\dhenv\Lib\site-packages\django\db\backends\base\base.py", line 316, in cursor
    return self._cursor()
           ^^^^^^^^^^^^^^
  File "C:\Users\genti\OneDrive\Documentos\gestao_eventos\dhenv\Lib\site-packages\django\db\backends\base\base.py", line 292, in _cursor
    self.ensure_connection()
  File "C:\Users\genti\OneDrive\Documentos\gestao_eventos\dhenv\Lib\site-packages\django\utils\asyncio.py", line 26, in inner
    return func(*args, **kwargs)
           ^^^^^^^^^^^^^^^^^^^^^
  File "C:\Users\genti\OneDrive\Documentos\gestao_eventos\dhenv\Lib\site-packages\django\db\backends\base\base.py", line 274, in ensure_connection
    with self.wrap_database_errors:
  File "C:\Users\genti\OneDrive\Documentos\gestao_eventos\dhenv\Lib\site-packages\django\db\utils.py", line 91, in __exit__
    raise dj_exc_value.with_traceback(traceback) from exc_value
  File "C:\Users\genti\OneDrive\Documentos\gestao_eventos\dhenv\Lib\site-packages\django\db\backends\base\base.py", line 275, in ensure_connection
    self.connect()
  File "C:\Users\genti\OneDrive\Documentos\gestao_eventos\dhenv\Lib\site-packages\django\utils\asyncio.py", line 26, in inner
    return func(*args, **kwargs)
           ^^^^^^^^^^^^^^^^^^^^^
  File "C:\Users\genti\OneDrive\Documentos\gestao_eventos\dhenv\Lib\site-packages\django\db\backends\base\base.py", line 256, in connect
    self.connection = self.get_new_connection(conn_params)
                      ^^^^^^^^^^^^^^^^^^^^^^^^^^^^^^^^^^^^
  File "C:\Users\genti\OneDrive\Documentos\gestao_eventos\dhenv\Lib\site-packages\django\utils\asyncio.py", line 26, in inner
    return func(*args, **kwargs)
           ^^^^^^^^^^^^^^^^^^^^^
  File "C:\Users\genti\OneDrive\Documentos\gestao_eventos\dhenv\Lib\site-packages\django\db\backends\postgresql\base.py", line 277, in get_new_connection
    connection = self.Database.connect(**conn_params)
                 ^^^^^^^^^^^^^^^^^^^^^^^^^^^^^^^^^^^^
  File "C:\Users\genti\OneDrive\Documentos\gestao_eventos\dhenv\Lib\site-packages\psycopg\connection.py", line 98, in connect
    attempts = conninfo_attempts(params)
               ^^^^^^^^^^^^^^^^^^^^^^^^^
  File "C:\Users\genti\OneDrive\Documentos\gestao_eventos\dhenv\Lib\site-packages\psycopg\_conninfo_attempts.py", line 50, in conninfo_attempts
    raise e.OperationalError(str(last_exc))
django.db.utils.OperationalError: [Errno 11001] getaddrinfo failed
Job "enviar_mensagens_agendadas (trigger: interval[0:01:00], next run at: 2025-01-31 13:38:44 AEDT)" raised an exception
Traceback (most recent call last):
  File "C:\Users\genti\OneDrive\Documentos\gestao_eventos\dhenv\Lib\site-packages\django\db\backends\base\base.py", line 275, in ensure_connection
    self.connect()
  File "C:\Users\genti\OneDrive\Documentos\gestao_eventos\dhenv\Lib\site-packages\django\utils\asyncio.py", line 26, in inner
    return func(*args, **kwargs)
           ^^^^^^^^^^^^^^^^^^^^^
  File "C:\Users\genti\OneDrive\Documentos\gestao_eventos\dhenv\Lib\site-packages\django\db\backends\base\base.py", line 256, in connect
    self.connection = self.get_new_connection(conn_params)
                      ^^^^^^^^^^^^^^^^^^^^^^^^^^^^^^^^^^^^
  File "C:\Users\genti\OneDrive\Documentos\gestao_eventos\dhenv\Lib\site-packages\django\utils\asyncio.py", line 26, in inner
    return func(*args, **kwargs)
           ^^^^^^^^^^^^^^^^^^^^^
  File "C:\Users\genti\OneDrive\Documentos\gestao_eventos\dhenv\Lib\site-packages\django\db\backends\postgresql\base.py", line 277, in get_new_connection
    connection = self.Database.connect(**conn_params)
                 ^^^^^^^^^^^^^^^^^^^^^^^^^^^^^^^^^^^^
  File "C:\Users\genti\OneDrive\Documentos\gestao_eventos\dhenv\Lib\site-packages\psycopg\connection.py", line 98, in connect
    attempts = conninfo_attempts(params)
               ^^^^^^^^^^^^^^^^^^^^^^^^^
  File "C:\Users\genti\OneDrive\Documentos\gestao_eventos\dhenv\Lib\site-packages\psycopg\_conninfo_attempts.py", line 50, in conninfo_attempts
    raise e.OperationalError(str(last_exc))
psycopg.OperationalError: [Errno 11001] getaddrinfo failed

The above exception was the direct cause of the following exception:

Traceback (most recent call last):
  File "C:\Users\genti\OneDrive\Documentos\gestao_eventos\dhenv\Lib\site-packages\apscheduler\executors\base.py", line 125, in run_job
    retval = job.func(*job.args, **job.kwargs)
             ^^^^^^^^^^^^^^^^^^^^^^^^^^^^^^^^^
  File "C:\Users\genti\OneDrive\Documentos\gestao_eventos\artistas\tasks.py", line 43, in enviar_mensagens_agendadas
    for artista in artistas:
  File "C:\Users\genti\OneDrive\Documentos\gestao_eventos\dhenv\Lib\site-packages\django\db\models\query.py", line 400, in __iter__
    self._fetch_all()
  File "C:\Users\genti\OneDrive\Documentos\gestao_eventos\dhenv\Lib\site-packages\django\db\models\query.py", line 1928, in _fetch_all
    self._result_cache = list(self._iterable_class(self))
                         ^^^^^^^^^^^^^^^^^^^^^^^^^^^^^^^^
  File "C:\Users\genti\OneDrive\Documentos\gestao_eventos\dhenv\Lib\site-packages\django\db\models\query.py", line 91, in __iter__
    results = compiler.execute_sql(
              ^^^^^^^^^^^^^^^^^^^^^
  File "C:\Users\genti\OneDrive\Documentos\gestao_eventos\dhenv\Lib\site-packages\django\db\models\sql\compiler.py", line 1560, in execute_sql
    cursor = self.connection.cursor()
             ^^^^^^^^^^^^^^^^^^^^^^^^
  File "C:\Users\genti\OneDrive\Documentos\gestao_eventos\dhenv\Lib\site-packages\django\utils\asyncio.py", line 26, in inner
    return func(*args, **kwargs)
           ^^^^^^^^^^^^^^^^^^^^^
  File "C:\Users\genti\OneDrive\Documentos\gestao_eventos\dhenv\Lib\site-packages\django\db\backends\base\base.py", line 316, in cursor
    return self._cursor()
           ^^^^^^^^^^^^^^
  File "C:\Users\genti\OneDrive\Documentos\gestao_eventos\dhenv\Lib\site-packages\django\db\backends\base\base.py", line 292, in _cursor
    self.ensure_connection()
  File "C:\Users\genti\OneDrive\Documentos\gestao_eventos\dhenv\Lib\site-packages\django\utils\asyncio.py", line 26, in inner
    return func(*args, **kwargs)
           ^^^^^^^^^^^^^^^^^^^^^
  File "C:\Users\genti\OneDrive\Documentos\gestao_eventos\dhenv\Lib\site-packages\django\db\backends\base\base.py", line 274, in ensure_connection
    with self.wrap_database_errors:
  File "C:\Users\genti\OneDrive\Documentos\gestao_eventos\dhenv\Lib\site-packages\django\db\utils.py", line 91, in __exit__
    raise dj_exc_value.with_traceback(traceback) from exc_value
  File "C:\Users\genti\OneDrive\Documentos\gestao_eventos\dhenv\Lib\site-packages\django\db\backends\base\base.py", line 275, in ensure_connection
    self.connect()
  File "C:\Users\genti\OneDrive\Documentos\gestao_eventos\dhenv\Lib\site-packages\django\utils\asyncio.py", line 26, in inner
    return func(*args, **kwargs)
           ^^^^^^^^^^^^^^^^^^^^^
  File "C:\Users\genti\OneDrive\Documentos\gestao_eventos\dhenv\Lib\site-packages\django\db\backends\base\base.py", line 256, in connect
    self.connection = self.get_new_connection(conn_params)
                      ^^^^^^^^^^^^^^^^^^^^^^^^^^^^^^^^^^^^
  File "C:\Users\genti\OneDrive\Documentos\gestao_eventos\dhenv\Lib\site-packages\django\utils\asyncio.py", line 26, in inner
    return func(*args, **kwargs)
           ^^^^^^^^^^^^^^^^^^^^^
  File "C:\Users\genti\OneDrive\Documentos\gestao_eventos\dhenv\Lib\site-packages\django\db\backends\postgresql\base.py", line 277, in get_new_connection
    connection = self.Database.connect(**conn_params)
                 ^^^^^^^^^^^^^^^^^^^^^^^^^^^^^^^^^^^^
  File "C:\Users\genti\OneDrive\Documentos\gestao_eventos\dhenv\Lib\site-packages\psycopg\connection.py", line 98, in connect
    attempts = conninfo_attempts(params)
               ^^^^^^^^^^^^^^^^^^^^^^^^^
  File "C:\Users\genti\OneDrive\Documentos\gestao_eventos\dhenv\Lib\site-packages\psycopg\_conninfo_attempts.py", line 50, in conninfo_attempts
    raise e.OperationalError(str(last_exc))
django.db.utils.OperationalError: [Errno 11001] getaddrinfo failed
Running job "enviar_mensagens_agendadas (trigger: interval[0:01:00], next run at: 2025-01-31 13:39:44 AEDT)" (scheduled at 2025-01-31 13:38:44.436381+11:00)
Running job "verificar_status (trigger: interval[0:01:00], next run at: 2025-01-31 13:39:44 AEDT)" (scheduled at 2025-01-31 13:38:44.436381+11:00)
Job "verificar_status (trigger: interval[0:01:00], next run at: 2025-01-31 13:39:44 AEDT)" raised an exception
Traceback (most recent call last):
  File "C:\Users\genti\OneDrive\Documentos\gestao_eventos\dhenv\Lib\site-packages\django\db\backends\base\base.py", line 275, in ensure_connection
    self.connect()
  File "C:\Users\genti\OneDrive\Documentos\gestao_eventos\dhenv\Lib\site-packages\django\utils\asyncio.py", line 26, in inner
    return func(*args, **kwargs)
           ^^^^^^^^^^^^^^^^^^^^^
  File "C:\Users\genti\OneDrive\Documentos\gestao_eventos\dhenv\Lib\site-packages\django\db\backends\base\base.py", line 256, in connect
    self.connection = self.get_new_connection(conn_params)
                      ^^^^^^^^^^^^^^^^^^^^^^^^^^^^^^^^^^^^
  File "C:\Users\genti\OneDrive\Documentos\gestao_eventos\dhenv\Lib\site-packages\django\utils\asyncio.py", line 26, in inner
    return func(*args, **kwargs)
           ^^^^^^^^^^^^^^^^^^^^^
  File "C:\Users\genti\OneDrive\Documentos\gestao_eventos\dhenv\Lib\site-packages\django\db\backends\postgresql\base.py", line 277, in get_new_connection
    connection = self.Database.connect(**conn_params)
                 ^^^^^^^^^^^^^^^^^^^^^^^^^^^^^^^^^^^^
  File "C:\Users\genti\OneDrive\Documentos\gestao_eventos\dhenv\Lib\site-packages\psycopg\connection.py", line 98, in connect
    attempts = conninfo_attempts(params)
               ^^^^^^^^^^^^^^^^^^^^^^^^^
  File "C:\Users\genti\OneDrive\Documentos\gestao_eventos\dhenv\Lib\site-packages\psycopg\_conninfo_attempts.py", line 50, in conninfo_attempts
    raise e.OperationalError(str(last_exc))
psycopg.OperationalError: [Errno 11001] getaddrinfo failed

The above exception was the direct cause of the following exception:

Traceback (most recent call last):
  File "C:\Users\genti\OneDrive\Documentos\gestao_eventos\dhenv\Lib\site-packages\apscheduler\executors\base.py", line 125, in run_job
    retval = job.func(*job.args, **job.kwargs)
             ^^^^^^^^^^^^^^^^^^^^^^^^^^^^^^^^^
  File "C:\Users\genti\OneDrive\Documentos\gestao_eventos\artistas\tasks.py", line 80, in verificar_status
    for artista in artistas:
  File "C:\Users\genti\OneDrive\Documentos\gestao_eventos\dhenv\Lib\site-packages\django\db\models\query.py", line 400, in __iter__
    self._fetch_all()
  File "C:\Users\genti\OneDrive\Documentos\gestao_eventos\dhenv\Lib\site-packages\django\db\models\query.py", line 1928, in _fetch_all
    self._result_cache = list(self._iterable_class(self))
                         ^^^^^^^^^^^^^^^^^^^^^^^^^^^^^^^^
  File "C:\Users\genti\OneDrive\Documentos\gestao_eventos\dhenv\Lib\site-packages\django\db\models\query.py", line 91, in __iter__
    results = compiler.execute_sql(
              ^^^^^^^^^^^^^^^^^^^^^
  File "C:\Users\genti\OneDrive\Documentos\gestao_eventos\dhenv\Lib\site-packages\django\db\models\sql\compiler.py", line 1560, in execute_sql
    cursor = self.connection.cursor()
             ^^^^^^^^^^^^^^^^^^^^^^^^
  File "C:\Users\genti\OneDrive\Documentos\gestao_eventos\dhenv\Lib\site-packages\django\utils\asyncio.py", line 26, in inner
    return func(*args, **kwargs)
           ^^^^^^^^^^^^^^^^^^^^^
  File "C:\Users\genti\OneDrive\Documentos\gestao_eventos\dhenv\Lib\site-packages\django\db\backends\base\base.py", line 316, in cursor
    return self._cursor()
           ^^^^^^^^^^^^^^
  File "C:\Users\genti\OneDrive\Documentos\gestao_eventos\dhenv\Lib\site-packages\django\db\backends\base\base.py", line 292, in _cursor
    self.ensure_connection()
  File "C:\Users\genti\OneDrive\Documentos\gestao_eventos\dhenv\Lib\site-packages\django\utils\asyncio.py", line 26, in inner
    return func(*args, **kwargs)
           ^^^^^^^^^^^^^^^^^^^^^
  File "C:\Users\genti\OneDrive\Documentos\gestao_eventos\dhenv\Lib\site-packages\django\db\backends\base\base.py", line 274, in ensure_connection
    with self.wrap_database_errors:
  File "C:\Users\genti\OneDrive\Documentos\gestao_eventos\dhenv\Lib\site-packages\django\db\utils.py", line 91, in __exit__
    raise dj_exc_value.with_traceback(traceback) from exc_value
  File "C:\Users\genti\OneDrive\Documentos\gestao_eventos\dhenv\Lib\site-packages\django\db\backends\base\base.py", line 275, in ensure_connection
    self.connect()
  File "C:\Users\genti\OneDrive\Documentos\gestao_eventos\dhenv\Lib\site-packages\django\utils\asyncio.py", line 26, in inner
    return func(*args, **kwargs)
           ^^^^^^^^^^^^^^^^^^^^^
  File "C:\Users\genti\OneDrive\Documentos\gestao_eventos\dhenv\Lib\site-packages\django\db\backends\base\base.py", line 256, in connect
    self.connection = self.get_new_connection(conn_params)
                      ^^^^^^^^^^^^^^^^^^^^^^^^^^^^^^^^^^^^
  File "C:\Users\genti\OneDrive\Documentos\gestao_eventos\dhenv\Lib\site-packages\django\utils\asyncio.py", line 26, in inner
    return func(*args, **kwargs)
           ^^^^^^^^^^^^^^^^^^^^^
  File "C:\Users\genti\OneDrive\Documentos\gestao_eventos\dhenv\Lib\site-packages\django\db\backends\postgresql\base.py", line 277, in get_new_connection
    connection = self.Database.connect(**conn_params)
                 ^^^^^^^^^^^^^^^^^^^^^^^^^^^^^^^^^^^^
  File "C:\Users\genti\OneDrive\Documentos\gestao_eventos\dhenv\Lib\site-packages\psycopg\connection.py", line 98, in connect
    attempts = conninfo_attempts(params)
               ^^^^^^^^^^^^^^^^^^^^^^^^^
  File "C:\Users\genti\OneDrive\Documentos\gestao_eventos\dhenv\Lib\site-packages\psycopg\_conninfo_attempts.py", line 50, in conninfo_attempts
    raise e.OperationalError(str(last_exc))
django.db.utils.OperationalError: [Errno 11001] getaddrinfo failed
Job "enviar_mensagens_agendadas (trigger: interval[0:01:00], next run at: 2025-01-31 13:39:44 AEDT)" raised an exception
Traceback (most recent call last):
  File "C:\Users\genti\OneDrive\Documentos\gestao_eventos\dhenv\Lib\site-packages\django\db\backends\base\base.py", line 275, in ensure_connection
    self.connect()
  File "C:\Users\genti\OneDrive\Documentos\gestao_eventos\dhenv\Lib\site-packages\django\utils\asyncio.py", line 26, in inner
    return func(*args, **kwargs)
           ^^^^^^^^^^^^^^^^^^^^^
  File "C:\Users\genti\OneDrive\Documentos\gestao_eventos\dhenv\Lib\site-packages\django\db\backends\base\base.py", line 256, in connect
    self.connection = self.get_new_connection(conn_params)
                      ^^^^^^^^^^^^^^^^^^^^^^^^^^^^^^^^^^^^
  File "C:\Users\genti\OneDrive\Documentos\gestao_eventos\dhenv\Lib\site-packages\django\utils\asyncio.py", line 26, in inner
    return func(*args, **kwargs)
           ^^^^^^^^^^^^^^^^^^^^^
  File "C:\Users\genti\OneDrive\Documentos\gestao_eventos\dhenv\Lib\site-packages\django\db\backends\postgresql\base.py", line 277, in get_new_connection
    connection = self.Database.connect(**conn_params)
                 ^^^^^^^^^^^^^^^^^^^^^^^^^^^^^^^^^^^^
  File "C:\Users\genti\OneDrive\Documentos\gestao_eventos\dhenv\Lib\site-packages\psycopg\connection.py", line 98, in connect
    attempts = conninfo_attempts(params)
               ^^^^^^^^^^^^^^^^^^^^^^^^^
  File "C:\Users\genti\OneDrive\Documentos\gestao_eventos\dhenv\Lib\site-packages\psycopg\_conninfo_attempts.py", line 50, in conninfo_attempts
    raise e.OperationalError(str(last_exc))
psycopg.OperationalError: [Errno 11001] getaddrinfo failed

The above exception was the direct cause of the following exception:

Traceback (most recent call last):
  File "C:\Users\genti\OneDrive\Documentos\gestao_eventos\dhenv\Lib\site-packages\apscheduler\executors\base.py", line 125, in run_job
    retval = job.func(*job.args, **job.kwargs)
             ^^^^^^^^^^^^^^^^^^^^^^^^^^^^^^^^^
  File "C:\Users\genti\OneDrive\Documentos\gestao_eventos\artistas\tasks.py", line 43, in enviar_mensagens_agendadas
    for artista in artistas:
  File "C:\Users\genti\OneDrive\Documentos\gestao_eventos\dhenv\Lib\site-packages\django\db\models\query.py", line 400, in __iter__
    self._fetch_all()
  File "C:\Users\genti\OneDrive\Documentos\gestao_eventos\dhenv\Lib\site-packages\django\db\models\query.py", line 1928, in _fetch_all
    self._result_cache = list(self._iterable_class(self))
                         ^^^^^^^^^^^^^^^^^^^^^^^^^^^^^^^^
  File "C:\Users\genti\OneDrive\Documentos\gestao_eventos\dhenv\Lib\site-packages\django\db\models\query.py", line 91, in __iter__
    results = compiler.execute_sql(
              ^^^^^^^^^^^^^^^^^^^^^
  File "C:\Users\genti\OneDrive\Documentos\gestao_eventos\dhenv\Lib\site-packages\django\db\models\sql\compiler.py", line 1560, in execute_sql
    cursor = self.connection.cursor()
             ^^^^^^^^^^^^^^^^^^^^^^^^
  File "C:\Users\genti\OneDrive\Documentos\gestao_eventos\dhenv\Lib\site-packages\django\utils\asyncio.py", line 26, in inner
    return func(*args, **kwargs)
           ^^^^^^^^^^^^^^^^^^^^^
  File "C:\Users\genti\OneDrive\Documentos\gestao_eventos\dhenv\Lib\site-packages\django\db\backends\base\base.py", line 316, in cursor
    return self._cursor()
           ^^^^^^^^^^^^^^
  File "C:\Users\genti\OneDrive\Documentos\gestao_eventos\dhenv\Lib\site-packages\django\db\backends\base\base.py", line 292, in _cursor
    self.ensure_connection()
  File "C:\Users\genti\OneDrive\Documentos\gestao_eventos\dhenv\Lib\site-packages\django\utils\asyncio.py", line 26, in inner
    return func(*args, **kwargs)
           ^^^^^^^^^^^^^^^^^^^^^
  File "C:\Users\genti\OneDrive\Documentos\gestao_eventos\dhenv\Lib\site-packages\django\db\backends\base\base.py", line 274, in ensure_connection
    with self.wrap_database_errors:
  File "C:\Users\genti\OneDrive\Documentos\gestao_eventos\dhenv\Lib\site-packages\django\db\utils.py", line 91, in __exit__
    raise dj_exc_value.with_traceback(traceback) from exc_value
  File "C:\Users\genti\OneDrive\Documentos\gestao_eventos\dhenv\Lib\site-packages\django\db\backends\base\base.py", line 275, in ensure_connection
    self.connect()
  File "C:\Users\genti\OneDrive\Documentos\gestao_eventos\dhenv\Lib\site-packages\django\utils\asyncio.py", line 26, in inner
    return func(*args, **kwargs)
           ^^^^^^^^^^^^^^^^^^^^^
  File "C:\Users\genti\OneDrive\Documentos\gestao_eventos\dhenv\Lib\site-packages\django\db\backends\base\base.py", line 256, in connect
    self.connection = self.get_new_connection(conn_params)
                      ^^^^^^^^^^^^^^^^^^^^^^^^^^^^^^^^^^^^
  File "C:\Users\genti\OneDrive\Documentos\gestao_eventos\dhenv\Lib\site-packages\django\utils\asyncio.py", line 26, in inner
    return func(*args, **kwargs)
           ^^^^^^^^^^^^^^^^^^^^^
  File "C:\Users\genti\OneDrive\Documentos\gestao_eventos\dhenv\Lib\site-packages\django\db\backends\postgresql\base.py", line 277, in get_new_connection
    connection = self.Database.connect(**conn_params)
                 ^^^^^^^^^^^^^^^^^^^^^^^^^^^^^^^^^^^^
  File "C:\Users\genti\OneDrive\Documentos\gestao_eventos\dhenv\Lib\site-packages\psycopg\connection.py", line 98, in connect
    attempts = conninfo_attempts(params)
               ^^^^^^^^^^^^^^^^^^^^^^^^^
  File "C:\Users\genti\OneDrive\Documentos\gestao_eventos\dhenv\Lib\site-packages\psycopg\_conninfo_attempts.py", line 50, in conninfo_attempts
    raise e.OperationalError(str(last_exc))
django.db.utils.OperationalError: [Errno 11001] getaddrinfo failed
Running job "enviar_mensagens_agendadas (trigger: interval[0:01:00], next run at: 2025-01-31 13:40:44 AEDT)" (scheduled at 2025-01-31 13:39:44.436381+11:00)
Running job "verificar_status (trigger: interval[0:01:00], next run at: 2025-01-31 13:40:44 AEDT)" (scheduled at 2025-01-31 13:39:44.436381+11:00)
Job "enviar_mensagens_agendadas (trigger: interval[0:01:00], next run at: 2025-01-31 13:40:44 AEDT)" raised an exception
Traceback (most recent call last):
  File "C:\Users\genti\OneDrive\Documentos\gestao_eventos\dhenv\Lib\site-packages\django\db\backends\base\base.py", line 275, in ensure_connection
    self.connect()
  File "C:\Users\genti\OneDrive\Documentos\gestao_eventos\dhenv\Lib\site-packages\django\utils\asyncio.py", line 26, in inner
    return func(*args, **kwargs)
           ^^^^^^^^^^^^^^^^^^^^^
  File "C:\Users\genti\OneDrive\Documentos\gestao_eventos\dhenv\Lib\site-packages\django\db\backends\base\base.py", line 256, in connect
    self.connection = self.get_new_connection(conn_params)
                      ^^^^^^^^^^^^^^^^^^^^^^^^^^^^^^^^^^^^
  File "C:\Users\genti\OneDrive\Documentos\gestao_eventos\dhenv\Lib\site-packages\django\utils\asyncio.py", line 26, in inner
    return func(*args, **kwargs)
           ^^^^^^^^^^^^^^^^^^^^^
  File "C:\Users\genti\OneDrive\Documentos\gestao_eventos\dhenv\Lib\site-packages\django\db\backends\postgresql\base.py", line 277, in get_new_connection
    connection = self.Database.connect(**conn_params)
                 ^^^^^^^^^^^^^^^^^^^^^^^^^^^^^^^^^^^^
  File "C:\Users\genti\OneDrive\Documentos\gestao_eventos\dhenv\Lib\site-packages\psycopg\connection.py", line 98, in connect
    attempts = conninfo_attempts(params)
               ^^^^^^^^^^^^^^^^^^^^^^^^^
  File "C:\Users\genti\OneDrive\Documentos\gestao_eventos\dhenv\Lib\site-packages\psycopg\_conninfo_attempts.py", line 50, in conninfo_attempts
    raise e.OperationalError(str(last_exc))
psycopg.OperationalError: [Errno 11001] getaddrinfo failed

The above exception was the direct cause of the following exception:

Traceback (most recent call last):
  File "C:\Users\genti\OneDrive\Documentos\gestao_eventos\dhenv\Lib\site-packages\apscheduler\executors\base.py", line 125, in run_job
    retval = job.func(*job.args, **job.kwargs)
             ^^^^^^^^^^^^^^^^^^^^^^^^^^^^^^^^^
  File "C:\Users\genti\OneDrive\Documentos\gestao_eventos\artistas\tasks.py", line 43, in enviar_mensagens_agendadas
    for artista in artistas:
  File "C:\Users\genti\OneDrive\Documentos\gestao_eventos\dhenv\Lib\site-packages\django\db\models\query.py", line 400, in __iter__
    self._fetch_all()
  File "C:\Users\genti\OneDrive\Documentos\gestao_eventos\dhenv\Lib\site-packages\django\db\models\query.py", line 1928, in _fetch_all
    self._result_cache = list(self._iterable_class(self))
                         ^^^^^^^^^^^^^^^^^^^^^^^^^^^^^^^^
  File "C:\Users\genti\OneDrive\Documentos\gestao_eventos\dhenv\Lib\site-packages\django\db\models\query.py", line 91, in __iter__
    results = compiler.execute_sql(
              ^^^^^^^^^^^^^^^^^^^^^
  File "C:\Users\genti\OneDrive\Documentos\gestao_eventos\dhenv\Lib\site-packages\django\db\models\sql\compiler.py", line 1560, in execute_sql
    cursor = self.connection.cursor()
             ^^^^^^^^^^^^^^^^^^^^^^^^
  File "C:\Users\genti\OneDrive\Documentos\gestao_eventos\dhenv\Lib\site-packages\django\utils\asyncio.py", line 26, in inner
    return func(*args, **kwargs)
           ^^^^^^^^^^^^^^^^^^^^^
  File "C:\Users\genti\OneDrive\Documentos\gestao_eventos\dhenv\Lib\site-packages\django\db\backends\base\base.py", line 316, in cursor
    return self._cursor()
           ^^^^^^^^^^^^^^
  File "C:\Users\genti\OneDrive\Documentos\gestao_eventos\dhenv\Lib\site-packages\django\db\backends\base\base.py", line 292, in _cursor
    self.ensure_connection()
  File "C:\Users\genti\OneDrive\Documentos\gestao_eventos\dhenv\Lib\site-packages\django\utils\asyncio.py", line 26, in inner
    return func(*args, **kwargs)
           ^^^^^^^^^^^^^^^^^^^^^
  File "C:\Users\genti\OneDrive\Documentos\gestao_eventos\dhenv\Lib\site-packages\django\db\backends\base\base.py", line 274, in ensure_connection
    with self.wrap_database_errors:
  File "C:\Users\genti\OneDrive\Documentos\gestao_eventos\dhenv\Lib\site-packages\django\db\utils.py", line 91, in __exit__
    raise dj_exc_value.with_traceback(traceback) from exc_value
  File "C:\Users\genti\OneDrive\Documentos\gestao_eventos\dhenv\Lib\site-packages\django\db\backends\base\base.py", line 275, in ensure_connection
    self.connect()
  File "C:\Users\genti\OneDrive\Documentos\gestao_eventos\dhenv\Lib\site-packages\django\utils\asyncio.py", line 26, in inner
    return func(*args, **kwargs)
           ^^^^^^^^^^^^^^^^^^^^^
  File "C:\Users\genti\OneDrive\Documentos\gestao_eventos\dhenv\Lib\site-packages\django\db\backends\base\base.py", line 256, in connect
    self.connection = self.get_new_connection(conn_params)
                      ^^^^^^^^^^^^^^^^^^^^^^^^^^^^^^^^^^^^
  File "C:\Users\genti\OneDrive\Documentos\gestao_eventos\dhenv\Lib\site-packages\django\utils\asyncio.py", line 26, in inner
    return func(*args, **kwargs)
           ^^^^^^^^^^^^^^^^^^^^^
  File "C:\Users\genti\OneDrive\Documentos\gestao_eventos\dhenv\Lib\site-packages\django\db\backends\postgresql\base.py", line 277, in get_new_connection
    connection = self.Database.connect(**conn_params)
                 ^^^^^^^^^^^^^^^^^^^^^^^^^^^^^^^^^^^^
  File "C:\Users\genti\OneDrive\Documentos\gestao_eventos\dhenv\Lib\site-packages\psycopg\connection.py", line 98, in connect
    attempts = conninfo_attempts(params)
               ^^^^^^^^^^^^^^^^^^^^^^^^^
  File "C:\Users\genti\OneDrive\Documentos\gestao_eventos\dhenv\Lib\site-packages\psycopg\_conninfo_attempts.py", line 50, in conninfo_attempts
    raise e.OperationalError(str(last_exc))
django.db.utils.OperationalError: [Errno 11001] getaddrinfo failed
Job "verificar_status (trigger: interval[0:01:00], next run at: 2025-01-31 13:40:44 AEDT)" raised an exception
Traceback (most recent call last):
  File "C:\Users\genti\OneDrive\Documentos\gestao_eventos\dhenv\Lib\site-packages\django\db\backends\base\base.py", line 275, in ensure_connection
    self.connect()
  File "C:\Users\genti\OneDrive\Documentos\gestao_eventos\dhenv\Lib\site-packages\django\utils\asyncio.py", line 26, in inner
    return func(*args, **kwargs)
           ^^^^^^^^^^^^^^^^^^^^^
  File "C:\Users\genti\OneDrive\Documentos\gestao_eventos\dhenv\Lib\site-packages\django\db\backends\base\base.py", line 256, in connect
    self.connection = self.get_new_connection(conn_params)
                      ^^^^^^^^^^^^^^^^^^^^^^^^^^^^^^^^^^^^
  File "C:\Users\genti\OneDrive\Documentos\gestao_eventos\dhenv\Lib\site-packages\django\utils\asyncio.py", line 26, in inner
    return func(*args, **kwargs)
           ^^^^^^^^^^^^^^^^^^^^^
  File "C:\Users\genti\OneDrive\Documentos\gestao_eventos\dhenv\Lib\site-packages\django\db\backends\postgresql\base.py", line 277, in get_new_connection
    connection = self.Database.connect(**conn_params)
                 ^^^^^^^^^^^^^^^^^^^^^^^^^^^^^^^^^^^^
  File "C:\Users\genti\OneDrive\Documentos\gestao_eventos\dhenv\Lib\site-packages\psycopg\connection.py", line 98, in connect
    attempts = conninfo_attempts(params)
               ^^^^^^^^^^^^^^^^^^^^^^^^^
  File "C:\Users\genti\OneDrive\Documentos\gestao_eventos\dhenv\Lib\site-packages\psycopg\_conninfo_attempts.py", line 50, in conninfo_attempts
    raise e.OperationalError(str(last_exc))
psycopg.OperationalError: [Errno 11001] getaddrinfo failed

The above exception was the direct cause of the following exception:

Traceback (most recent call last):
  File "C:\Users\genti\OneDrive\Documentos\gestao_eventos\dhenv\Lib\site-packages\apscheduler\executors\base.py", line 125, in run_job
    retval = job.func(*job.args, **job.kwargs)
             ^^^^^^^^^^^^^^^^^^^^^^^^^^^^^^^^^
  File "C:\Users\genti\OneDrive\Documentos\gestao_eventos\artistas\tasks.py", line 80, in verificar_status
    for artista in artistas:
  File "C:\Users\genti\OneDrive\Documentos\gestao_eventos\dhenv\Lib\site-packages\django\db\models\query.py", line 400, in __iter__
    self._fetch_all()
  File "C:\Users\genti\OneDrive\Documentos\gestao_eventos\dhenv\Lib\site-packages\django\db\models\query.py", line 1928, in _fetch_all
    self._result_cache = list(self._iterable_class(self))
                         ^^^^^^^^^^^^^^^^^^^^^^^^^^^^^^^^
  File "C:\Users\genti\OneDrive\Documentos\gestao_eventos\dhenv\Lib\site-packages\django\db\models\query.py", line 91, in __iter__
    results = compiler.execute_sql(
              ^^^^^^^^^^^^^^^^^^^^^
  File "C:\Users\genti\OneDrive\Documentos\gestao_eventos\dhenv\Lib\site-packages\django\db\models\sql\compiler.py", line 1560, in execute_sql
    cursor = self.connection.cursor()
             ^^^^^^^^^^^^^^^^^^^^^^^^
  File "C:\Users\genti\OneDrive\Documentos\gestao_eventos\dhenv\Lib\site-packages\django\utils\asyncio.py", line 26, in inner
    return func(*args, **kwargs)
           ^^^^^^^^^^^^^^^^^^^^^
  File "C:\Users\genti\OneDrive\Documentos\gestao_eventos\dhenv\Lib\site-packages\django\db\backends\base\base.py", line 316, in cursor
    return self._cursor()
           ^^^^^^^^^^^^^^
  File "C:\Users\genti\OneDrive\Documentos\gestao_eventos\dhenv\Lib\site-packages\django\db\backends\base\base.py", line 292, in _cursor
    self.ensure_connection()
  File "C:\Users\genti\OneDrive\Documentos\gestao_eventos\dhenv\Lib\site-packages\django\utils\asyncio.py", line 26, in inner
    return func(*args, **kwargs)
           ^^^^^^^^^^^^^^^^^^^^^
  File "C:\Users\genti\OneDrive\Documentos\gestao_eventos\dhenv\Lib\site-packages\django\db\backends\base\base.py", line 274, in ensure_connection
    with self.wrap_database_errors:
  File "C:\Users\genti\OneDrive\Documentos\gestao_eventos\dhenv\Lib\site-packages\django\db\utils.py", line 91, in __exit__
    raise dj_exc_value.with_traceback(traceback) from exc_value
  File "C:\Users\genti\OneDrive\Documentos\gestao_eventos\dhenv\Lib\site-packages\django\db\backends\base\base.py", line 275, in ensure_connection
    self.connect()
  File "C:\Users\genti\OneDrive\Documentos\gestao_eventos\dhenv\Lib\site-packages\django\utils\asyncio.py", line 26, in inner
    return func(*args, **kwargs)
           ^^^^^^^^^^^^^^^^^^^^^
  File "C:\Users\genti\OneDrive\Documentos\gestao_eventos\dhenv\Lib\site-packages\django\db\backends\base\base.py", line 256, in connect
    self.connection = self.get_new_connection(conn_params)
                      ^^^^^^^^^^^^^^^^^^^^^^^^^^^^^^^^^^^^
  File "C:\Users\genti\OneDrive\Documentos\gestao_eventos\dhenv\Lib\site-packages\django\utils\asyncio.py", line 26, in inner
    return func(*args, **kwargs)
           ^^^^^^^^^^^^^^^^^^^^^
  File "C:\Users\genti\OneDrive\Documentos\gestao_eventos\dhenv\Lib\site-packages\django\db\backends\postgresql\base.py", line 277, in get_new_connection
    connection = self.Database.connect(**conn_params)
                 ^^^^^^^^^^^^^^^^^^^^^^^^^^^^^^^^^^^^
  File "C:\Users\genti\OneDrive\Documentos\gestao_eventos\dhenv\Lib\site-packages\psycopg\connection.py", line 98, in connect
    attempts = conninfo_attempts(params)
               ^^^^^^^^^^^^^^^^^^^^^^^^^
  File "C:\Users\genti\OneDrive\Documentos\gestao_eventos\dhenv\Lib\site-packages\psycopg\_conninfo_attempts.py", line 50, in conninfo_attempts
    raise e.OperationalError(str(last_exc))
django.db.utils.OperationalError: [Errno 11001] getaddrinfo failed
Scheduler started
Not Found: /favicon.ico
"GET /favicon.ico HTTP/1.1" 404 3303
Artista 7 com informações incompletas.
Artista 6 com informações incompletas.
Artista 7 com informações incompletas.
Artista 6 com informações incompletas.
Scheduler started
Session data corrupted
Session data corrupted
Session data corrupted
Artista 7 com informações incompletas.
Artista 6 com informações incompletas.
Scheduler started
Scheduler started
Not Found: /favicon.ico
"GET /favicon.ico HTTP/1.1" 404 3303
Artista 7 com informações incompletas.
Artista 6 com informações incompletas.
Artista 7 com informações incompletas.
Artista 6 com informações incompletas.
Artista 7 com informações incompletas.
Artista 6 com informações incompletas.
Scheduler started
Artista 7 com informações incompletas.
Artista 6 com informações incompletas.
Artista 7 com informações incompletas.
Artista 6 com informações incompletas.
Scheduler started
Running job "enviar_mensagens_agendadas (trigger: interval[0:01:00], next run at: 2025-02-05 15:47:28 AEDT)" (scheduled at 2025-02-05 15:46:28.343640+11:00)
Running job "verificar_status (trigger: interval[0:01:00], next run at: 2025-02-05 15:47:28 AEDT)" (scheduled at 2025-02-05 15:46:28.343640+11:00)
Execution of job "enviar_mensagens_agendadas (trigger: interval[0:01:00], next run at: 2025-02-05 15:47:28 AEDT)" skipped: maximum number of running instances reached (1)
Execution of job "verificar_status (trigger: interval[0:01:00], next run at: 2025-02-05 15:47:28 AEDT)" skipped: maximum number of running instances reached (1)
Execution of job "enviar_mensagens_agendadas (trigger: interval[0:01:00], next run at: 2025-02-05 15:48:28 AEDT)" skipped: maximum number of running instances reached (1)
Execution of job "verificar_status (trigger: interval[0:01:00], next run at: 2025-02-05 15:48:28 AEDT)" skipped: maximum number of running instances reached (1)
Job "verificar_status (trigger: interval[0:01:00], next run at: 2025-02-05 15:49:28 AEDT)" raised an exception
Traceback (most recent call last):
  File "C:\Users\genti\OneDrive\Documentos\gestao_eventos\dhenv\Lib\site-packages\django\db\backends\base\base.py", line 275, in ensure_connection
    self.connect()
  File "C:\Users\genti\OneDrive\Documentos\gestao_eventos\dhenv\Lib\site-packages\django\utils\asyncio.py", line 26, in inner
    return func(*args, **kwargs)
           ^^^^^^^^^^^^^^^^^^^^^
  File "C:\Users\genti\OneDrive\Documentos\gestao_eventos\dhenv\Lib\site-packages\django\db\backends\base\base.py", line 256, in connect
    self.connection = self.get_new_connection(conn_params)
                      ^^^^^^^^^^^^^^^^^^^^^^^^^^^^^^^^^^^^
  File "C:\Users\genti\OneDrive\Documentos\gestao_eventos\dhenv\Lib\site-packages\django\utils\asyncio.py", line 26, in inner
    return func(*args, **kwargs)
           ^^^^^^^^^^^^^^^^^^^^^
  File "C:\Users\genti\OneDrive\Documentos\gestao_eventos\dhenv\Lib\site-packages\django\db\backends\postgresql\base.py", line 277, in get_new_connection
    connection = self.Database.connect(**conn_params)
                 ^^^^^^^^^^^^^^^^^^^^^^^^^^^^^^^^^^^^
  File "C:\Users\genti\OneDrive\Documentos\gestao_eventos\dhenv\Lib\site-packages\psycopg\connection.py", line 119, in connect
    raise last_ex.with_traceback(None)
psycopg.OperationalError: connection failed: connection to server at "35.212.52.114", port 17037 failed: server closed the connection unexpectedly
	This probably means the server terminated abnormally
	before or while processing the request.

The above exception was the direct cause of the following exception:

Traceback (most recent call last):
  File "C:\Users\genti\OneDrive\Documentos\gestao_eventos\dhenv\Lib\site-packages\apscheduler\executors\base.py", line 125, in run_job
    retval = job.func(*job.args, **job.kwargs)
             ^^^^^^^^^^^^^^^^^^^^^^^^^^^^^^^^^
  File "C:\Users\genti\OneDrive\Documentos\gestao_eventos\artistas\tasks.py", line 80, in verificar_status
    for artista in artistas:
  File "C:\Users\genti\OneDrive\Documentos\gestao_eventos\dhenv\Lib\site-packages\django\db\models\query.py", line 400, in __iter__
    self._fetch_all()
  File "C:\Users\genti\OneDrive\Documentos\gestao_eventos\dhenv\Lib\site-packages\django\db\models\query.py", line 1928, in _fetch_all
    self._result_cache = list(self._iterable_class(self))
                         ^^^^^^^^^^^^^^^^^^^^^^^^^^^^^^^^
  File "C:\Users\genti\OneDrive\Documentos\gestao_eventos\dhenv\Lib\site-packages\django\db\models\query.py", line 91, in __iter__
    results = compiler.execute_sql(
              ^^^^^^^^^^^^^^^^^^^^^
  File "C:\Users\genti\OneDrive\Documentos\gestao_eventos\dhenv\Lib\site-packages\django\db\models\sql\compiler.py", line 1560, in execute_sql
    cursor = self.connection.cursor()
             ^^^^^^^^^^^^^^^^^^^^^^^^
  File "C:\Users\genti\OneDrive\Documentos\gestao_eventos\dhenv\Lib\site-packages\django\utils\asyncio.py", line 26, in inner
    return func(*args, **kwargs)
           ^^^^^^^^^^^^^^^^^^^^^
  File "C:\Users\genti\OneDrive\Documentos\gestao_eventos\dhenv\Lib\site-packages\django\db\backends\base\base.py", line 316, in cursor
    return self._cursor()
           ^^^^^^^^^^^^^^
  File "C:\Users\genti\OneDrive\Documentos\gestao_eventos\dhenv\Lib\site-packages\django\db\backends\base\base.py", line 292, in _cursor
    self.ensure_connection()
  File "C:\Users\genti\OneDrive\Documentos\gestao_eventos\dhenv\Lib\site-packages\django\utils\asyncio.py", line 26, in inner
    return func(*args, **kwargs)
           ^^^^^^^^^^^^^^^^^^^^^
  File "C:\Users\genti\OneDrive\Documentos\gestao_eventos\dhenv\Lib\site-packages\django\db\backends\base\base.py", line 274, in ensure_connection
    with self.wrap_database_errors:
  File "C:\Users\genti\OneDrive\Documentos\gestao_eventos\dhenv\Lib\site-packages\django\db\utils.py", line 91, in __exit__
    raise dj_exc_value.with_traceback(traceback) from exc_value
  File "C:\Users\genti\OneDrive\Documentos\gestao_eventos\dhenv\Lib\site-packages\django\db\backends\base\base.py", line 275, in ensure_connection
    self.connect()
  File "C:\Users\genti\OneDrive\Documentos\gestao_eventos\dhenv\Lib\site-packages\django\utils\asyncio.py", line 26, in inner
    return func(*args, **kwargs)
           ^^^^^^^^^^^^^^^^^^^^^
  File "C:\Users\genti\OneDrive\Documentos\gestao_eventos\dhenv\Lib\site-packages\django\db\backends\base\base.py", line 256, in connect
    self.connection = self.get_new_connection(conn_params)
                      ^^^^^^^^^^^^^^^^^^^^^^^^^^^^^^^^^^^^
  File "C:\Users\genti\OneDrive\Documentos\gestao_eventos\dhenv\Lib\site-packages\django\utils\asyncio.py", line 26, in inner
    return func(*args, **kwargs)
           ^^^^^^^^^^^^^^^^^^^^^
  File "C:\Users\genti\OneDrive\Documentos\gestao_eventos\dhenv\Lib\site-packages\django\db\backends\postgresql\base.py", line 277, in get_new_connection
    connection = self.Database.connect(**conn_params)
                 ^^^^^^^^^^^^^^^^^^^^^^^^^^^^^^^^^^^^
  File "C:\Users\genti\OneDrive\Documentos\gestao_eventos\dhenv\Lib\site-packages\psycopg\connection.py", line 119, in connect
    raise last_ex.with_traceback(None)
django.db.utils.OperationalError: connection failed: connection to server at "35.212.52.114", port 17037 failed: server closed the connection unexpectedly
	This probably means the server terminated abnormally
	before or while processing the request.
Job "enviar_mensagens_agendadas (trigger: interval[0:01:00], next run at: 2025-02-05 15:49:28 AEDT)" raised an exception
Traceback (most recent call last):
  File "C:\Users\genti\OneDrive\Documentos\gestao_eventos\dhenv\Lib\site-packages\django\db\backends\base\base.py", line 275, in ensure_connection
    self.connect()
  File "C:\Users\genti\OneDrive\Documentos\gestao_eventos\dhenv\Lib\site-packages\django\utils\asyncio.py", line 26, in inner
    return func(*args, **kwargs)
           ^^^^^^^^^^^^^^^^^^^^^
  File "C:\Users\genti\OneDrive\Documentos\gestao_eventos\dhenv\Lib\site-packages\django\db\backends\base\base.py", line 256, in connect
    self.connection = self.get_new_connection(conn_params)
                      ^^^^^^^^^^^^^^^^^^^^^^^^^^^^^^^^^^^^
  File "C:\Users\genti\OneDrive\Documentos\gestao_eventos\dhenv\Lib\site-packages\django\utils\asyncio.py", line 26, in inner
    return func(*args, **kwargs)
           ^^^^^^^^^^^^^^^^^^^^^
  File "C:\Users\genti\OneDrive\Documentos\gestao_eventos\dhenv\Lib\site-packages\django\db\backends\postgresql\base.py", line 277, in get_new_connection
    connection = self.Database.connect(**conn_params)
                 ^^^^^^^^^^^^^^^^^^^^^^^^^^^^^^^^^^^^
  File "C:\Users\genti\OneDrive\Documentos\gestao_eventos\dhenv\Lib\site-packages\psycopg\connection.py", line 119, in connect
    raise last_ex.with_traceback(None)
psycopg.errors.ConnectionTimeout: connection timeout expired

The above exception was the direct cause of the following exception:

Traceback (most recent call last):
  File "C:\Users\genti\OneDrive\Documentos\gestao_eventos\dhenv\Lib\site-packages\apscheduler\executors\base.py", line 125, in run_job
    retval = job.func(*job.args, **job.kwargs)
             ^^^^^^^^^^^^^^^^^^^^^^^^^^^^^^^^^
  File "C:\Users\genti\OneDrive\Documentos\gestao_eventos\artistas\tasks.py", line 43, in enviar_mensagens_agendadas
    for artista in artistas:
  File "C:\Users\genti\OneDrive\Documentos\gestao_eventos\dhenv\Lib\site-packages\django\db\models\query.py", line 400, in __iter__
    self._fetch_all()
  File "C:\Users\genti\OneDrive\Documentos\gestao_eventos\dhenv\Lib\site-packages\django\db\models\query.py", line 1928, in _fetch_all
    self._result_cache = list(self._iterable_class(self))
                         ^^^^^^^^^^^^^^^^^^^^^^^^^^^^^^^^
  File "C:\Users\genti\OneDrive\Documentos\gestao_eventos\dhenv\Lib\site-packages\django\db\models\query.py", line 91, in __iter__
    results = compiler.execute_sql(
              ^^^^^^^^^^^^^^^^^^^^^
  File "C:\Users\genti\OneDrive\Documentos\gestao_eventos\dhenv\Lib\site-packages\django\db\models\sql\compiler.py", line 1560, in execute_sql
    cursor = self.connection.cursor()
             ^^^^^^^^^^^^^^^^^^^^^^^^
  File "C:\Users\genti\OneDrive\Documentos\gestao_eventos\dhenv\Lib\site-packages\django\utils\asyncio.py", line 26, in inner
    return func(*args, **kwargs)
           ^^^^^^^^^^^^^^^^^^^^^
  File "C:\Users\genti\OneDrive\Documentos\gestao_eventos\dhenv\Lib\site-packages\django\db\backends\base\base.py", line 316, in cursor
    return self._cursor()
           ^^^^^^^^^^^^^^
  File "C:\Users\genti\OneDrive\Documentos\gestao_eventos\dhenv\Lib\site-packages\django\db\backends\base\base.py", line 292, in _cursor
    self.ensure_connection()
  File "C:\Users\genti\OneDrive\Documentos\gestao_eventos\dhenv\Lib\site-packages\django\utils\asyncio.py", line 26, in inner
    return func(*args, **kwargs)
           ^^^^^^^^^^^^^^^^^^^^^
  File "C:\Users\genti\OneDrive\Documentos\gestao_eventos\dhenv\Lib\site-packages\django\db\backends\base\base.py", line 274, in ensure_connection
    with self.wrap_database_errors:
  File "C:\Users\genti\OneDrive\Documentos\gestao_eventos\dhenv\Lib\site-packages\django\db\utils.py", line 91, in __exit__
    raise dj_exc_value.with_traceback(traceback) from exc_value
  File "C:\Users\genti\OneDrive\Documentos\gestao_eventos\dhenv\Lib\site-packages\django\db\backends\base\base.py", line 275, in ensure_connection
    self.connect()
  File "C:\Users\genti\OneDrive\Documentos\gestao_eventos\dhenv\Lib\site-packages\django\utils\asyncio.py", line 26, in inner
    return func(*args, **kwargs)
           ^^^^^^^^^^^^^^^^^^^^^
  File "C:\Users\genti\OneDrive\Documentos\gestao_eventos\dhenv\Lib\site-packages\django\db\backends\base\base.py", line 256, in connect
    self.connection = self.get_new_connection(conn_params)
                      ^^^^^^^^^^^^^^^^^^^^^^^^^^^^^^^^^^^^
  File "C:\Users\genti\OneDrive\Documentos\gestao_eventos\dhenv\Lib\site-packages\django\utils\asyncio.py", line 26, in inner
    return func(*args, **kwargs)
           ^^^^^^^^^^^^^^^^^^^^^
  File "C:\Users\genti\OneDrive\Documentos\gestao_eventos\dhenv\Lib\site-packages\django\db\backends\postgresql\base.py", line 277, in get_new_connection
    connection = self.Database.connect(**conn_params)
                 ^^^^^^^^^^^^^^^^^^^^^^^^^^^^^^^^^^^^
  File "C:\Users\genti\OneDrive\Documentos\gestao_eventos\dhenv\Lib\site-packages\psycopg\connection.py", line 119, in connect
    raise last_ex.with_traceback(None)
django.db.utils.OperationalError: connection timeout expired
Running job "enviar_mensagens_agendadas (trigger: interval[0:01:00], next run at: 2025-02-05 15:50:28 AEDT)" (scheduled at 2025-02-05 15:49:28.343640+11:00)
Running job "verificar_status (trigger: interval[0:01:00], next run at: 2025-02-05 15:50:28 AEDT)" (scheduled at 2025-02-05 15:49:28.343640+11:00)
Execution of job "enviar_mensagens_agendadas (trigger: interval[0:01:00], next run at: 2025-02-05 15:50:28 AEDT)" skipped: maximum number of running instances reached (1)
Execution of job "verificar_status (trigger: interval[0:01:00], next run at: 2025-02-05 15:50:28 AEDT)" skipped: maximum number of running instances reached (1)
Execution of job "enviar_mensagens_agendadas (trigger: interval[0:01:00], next run at: 2025-02-05 15:51:28 AEDT)" skipped: maximum number of running instances reached (1)
Execution of job "verificar_status (trigger: interval[0:01:00], next run at: 2025-02-05 15:51:28 AEDT)" skipped: maximum number of running instances reached (1)
Job "enviar_mensagens_agendadas (trigger: interval[0:01:00], next run at: 2025-02-05 15:52:28 AEDT)" raised an exception
Traceback (most recent call last):
  File "C:\Users\genti\OneDrive\Documentos\gestao_eventos\dhenv\Lib\site-packages\django\db\backends\base\base.py", line 275, in ensure_connection
    self.connect()
  File "C:\Users\genti\OneDrive\Documentos\gestao_eventos\dhenv\Lib\site-packages\django\utils\asyncio.py", line 26, in inner
    return func(*args, **kwargs)
           ^^^^^^^^^^^^^^^^^^^^^
  File "C:\Users\genti\OneDrive\Documentos\gestao_eventos\dhenv\Lib\site-packages\django\db\backends\base\base.py", line 256, in connect
    self.connection = self.get_new_connection(conn_params)
                      ^^^^^^^^^^^^^^^^^^^^^^^^^^^^^^^^^^^^
  File "C:\Users\genti\OneDrive\Documentos\gestao_eventos\dhenv\Lib\site-packages\django\utils\asyncio.py", line 26, in inner
    return func(*args, **kwargs)
           ^^^^^^^^^^^^^^^^^^^^^
  File "C:\Users\genti\OneDrive\Documentos\gestao_eventos\dhenv\Lib\site-packages\django\db\backends\postgresql\base.py", line 277, in get_new_connection
    connection = self.Database.connect(**conn_params)
                 ^^^^^^^^^^^^^^^^^^^^^^^^^^^^^^^^^^^^
  File "C:\Users\genti\OneDrive\Documentos\gestao_eventos\dhenv\Lib\site-packages\psycopg\connection.py", line 119, in connect
    raise last_ex.with_traceback(None)
psycopg.errors.ConnectionTimeout: connection timeout expired

The above exception was the direct cause of the following exception:

Traceback (most recent call last):
  File "C:\Users\genti\OneDrive\Documentos\gestao_eventos\dhenv\Lib\site-packages\apscheduler\executors\base.py", line 125, in run_job
    retval = job.func(*job.args, **job.kwargs)
             ^^^^^^^^^^^^^^^^^^^^^^^^^^^^^^^^^
  File "C:\Users\genti\OneDrive\Documentos\gestao_eventos\artistas\tasks.py", line 43, in enviar_mensagens_agendadas
    for artista in artistas:
  File "C:\Users\genti\OneDrive\Documentos\gestao_eventos\dhenv\Lib\site-packages\django\db\models\query.py", line 400, in __iter__
    self._fetch_all()
  File "C:\Users\genti\OneDrive\Documentos\gestao_eventos\dhenv\Lib\site-packages\django\db\models\query.py", line 1928, in _fetch_all
    self._result_cache = list(self._iterable_class(self))
                         ^^^^^^^^^^^^^^^^^^^^^^^^^^^^^^^^
  File "C:\Users\genti\OneDrive\Documentos\gestao_eventos\dhenv\Lib\site-packages\django\db\models\query.py", line 91, in __iter__
    results = compiler.execute_sql(
              ^^^^^^^^^^^^^^^^^^^^^
  File "C:\Users\genti\OneDrive\Documentos\gestao_eventos\dhenv\Lib\site-packages\django\db\models\sql\compiler.py", line 1560, in execute_sql
    cursor = self.connection.cursor()
             ^^^^^^^^^^^^^^^^^^^^^^^^
  File "C:\Users\genti\OneDrive\Documentos\gestao_eventos\dhenv\Lib\site-packages\django\utils\asyncio.py", line 26, in inner
    return func(*args, **kwargs)
           ^^^^^^^^^^^^^^^^^^^^^
  File "C:\Users\genti\OneDrive\Documentos\gestao_eventos\dhenv\Lib\site-packages\django\db\backends\base\base.py", line 316, in cursor
    return self._cursor()
           ^^^^^^^^^^^^^^
  File "C:\Users\genti\OneDrive\Documentos\gestao_eventos\dhenv\Lib\site-packages\django\db\backends\base\base.py", line 292, in _cursor
    self.ensure_connection()
  File "C:\Users\genti\OneDrive\Documentos\gestao_eventos\dhenv\Lib\site-packages\django\utils\asyncio.py", line 26, in inner
    return func(*args, **kwargs)
           ^^^^^^^^^^^^^^^^^^^^^
  File "C:\Users\genti\OneDrive\Documentos\gestao_eventos\dhenv\Lib\site-packages\django\db\backends\base\base.py", line 274, in ensure_connection
    with self.wrap_database_errors:
  File "C:\Users\genti\OneDrive\Documentos\gestao_eventos\dhenv\Lib\site-packages\django\db\utils.py", line 91, in __exit__
    raise dj_exc_value.with_traceback(traceback) from exc_value
  File "C:\Users\genti\OneDrive\Documentos\gestao_eventos\dhenv\Lib\site-packages\django\db\backends\base\base.py", line 275, in ensure_connection
    self.connect()
  File "C:\Users\genti\OneDrive\Documentos\gestao_eventos\dhenv\Lib\site-packages\django\utils\asyncio.py", line 26, in inner
    return func(*args, **kwargs)
           ^^^^^^^^^^^^^^^^^^^^^
  File "C:\Users\genti\OneDrive\Documentos\gestao_eventos\dhenv\Lib\site-packages\django\db\backends\base\base.py", line 256, in connect
    self.connection = self.get_new_connection(conn_params)
                      ^^^^^^^^^^^^^^^^^^^^^^^^^^^^^^^^^^^^
  File "C:\Users\genti\OneDrive\Documentos\gestao_eventos\dhenv\Lib\site-packages\django\utils\asyncio.py", line 26, in inner
    return func(*args, **kwargs)
           ^^^^^^^^^^^^^^^^^^^^^
  File "C:\Users\genti\OneDrive\Documentos\gestao_eventos\dhenv\Lib\site-packages\django\db\backends\postgresql\base.py", line 277, in get_new_connection
    connection = self.Database.connect(**conn_params)
                 ^^^^^^^^^^^^^^^^^^^^^^^^^^^^^^^^^^^^
  File "C:\Users\genti\OneDrive\Documentos\gestao_eventos\dhenv\Lib\site-packages\psycopg\connection.py", line 119, in connect
    raise last_ex.with_traceback(None)
django.db.utils.OperationalError: connection timeout expired
Job "verificar_status (trigger: interval[0:01:00], next run at: 2025-02-05 15:52:28 AEDT)" raised an exception
Traceback (most recent call last):
  File "C:\Users\genti\OneDrive\Documentos\gestao_eventos\dhenv\Lib\site-packages\django\db\backends\base\base.py", line 275, in ensure_connection
    self.connect()
  File "C:\Users\genti\OneDrive\Documentos\gestao_eventos\dhenv\Lib\site-packages\django\utils\asyncio.py", line 26, in inner
    return func(*args, **kwargs)
           ^^^^^^^^^^^^^^^^^^^^^
  File "C:\Users\genti\OneDrive\Documentos\gestao_eventos\dhenv\Lib\site-packages\django\db\backends\base\base.py", line 256, in connect
    self.connection = self.get_new_connection(conn_params)
                      ^^^^^^^^^^^^^^^^^^^^^^^^^^^^^^^^^^^^
  File "C:\Users\genti\OneDrive\Documentos\gestao_eventos\dhenv\Lib\site-packages\django\utils\asyncio.py", line 26, in inner
    return func(*args, **kwargs)
           ^^^^^^^^^^^^^^^^^^^^^
  File "C:\Users\genti\OneDrive\Documentos\gestao_eventos\dhenv\Lib\site-packages\django\db\backends\postgresql\base.py", line 277, in get_new_connection
    connection = self.Database.connect(**conn_params)
                 ^^^^^^^^^^^^^^^^^^^^^^^^^^^^^^^^^^^^
  File "C:\Users\genti\OneDrive\Documentos\gestao_eventos\dhenv\Lib\site-packages\psycopg\connection.py", line 119, in connect
    raise last_ex.with_traceback(None)
psycopg.errors.ConnectionTimeout: connection timeout expired

The above exception was the direct cause of the following exception:

Traceback (most recent call last):
  File "C:\Users\genti\OneDrive\Documentos\gestao_eventos\dhenv\Lib\site-packages\apscheduler\executors\base.py", line 125, in run_job
    retval = job.func(*job.args, **job.kwargs)
             ^^^^^^^^^^^^^^^^^^^^^^^^^^^^^^^^^
  File "C:\Users\genti\OneDrive\Documentos\gestao_eventos\artistas\tasks.py", line 80, in verificar_status
    for artista in artistas:
  File "C:\Users\genti\OneDrive\Documentos\gestao_eventos\dhenv\Lib\site-packages\django\db\models\query.py", line 400, in __iter__
    self._fetch_all()
  File "C:\Users\genti\OneDrive\Documentos\gestao_eventos\dhenv\Lib\site-packages\django\db\models\query.py", line 1928, in _fetch_all
    self._result_cache = list(self._iterable_class(self))
                         ^^^^^^^^^^^^^^^^^^^^^^^^^^^^^^^^
  File "C:\Users\genti\OneDrive\Documentos\gestao_eventos\dhenv\Lib\site-packages\django\db\models\query.py", line 91, in __iter__
    results = compiler.execute_sql(
              ^^^^^^^^^^^^^^^^^^^^^
  File "C:\Users\genti\OneDrive\Documentos\gestao_eventos\dhenv\Lib\site-packages\django\db\models\sql\compiler.py", line 1560, in execute_sql
    cursor = self.connection.cursor()
             ^^^^^^^^^^^^^^^^^^^^^^^^
  File "C:\Users\genti\OneDrive\Documentos\gestao_eventos\dhenv\Lib\site-packages\django\utils\asyncio.py", line 26, in inner
    return func(*args, **kwargs)
           ^^^^^^^^^^^^^^^^^^^^^
  File "C:\Users\genti\OneDrive\Documentos\gestao_eventos\dhenv\Lib\site-packages\django\db\backends\base\base.py", line 316, in cursor
    return self._cursor()
           ^^^^^^^^^^^^^^
  File "C:\Users\genti\OneDrive\Documentos\gestao_eventos\dhenv\Lib\site-packages\django\db\backends\base\base.py", line 292, in _cursor
    self.ensure_connection()
  File "C:\Users\genti\OneDrive\Documentos\gestao_eventos\dhenv\Lib\site-packages\django\utils\asyncio.py", line 26, in inner
    return func(*args, **kwargs)
           ^^^^^^^^^^^^^^^^^^^^^
  File "C:\Users\genti\OneDrive\Documentos\gestao_eventos\dhenv\Lib\site-packages\django\db\backends\base\base.py", line 274, in ensure_connection
    with self.wrap_database_errors:
  File "C:\Users\genti\OneDrive\Documentos\gestao_eventos\dhenv\Lib\site-packages\django\db\utils.py", line 91, in __exit__
    raise dj_exc_value.with_traceback(traceback) from exc_value
  File "C:\Users\genti\OneDrive\Documentos\gestao_eventos\dhenv\Lib\site-packages\django\db\backends\base\base.py", line 275, in ensure_connection
    self.connect()
  File "C:\Users\genti\OneDrive\Documentos\gestao_eventos\dhenv\Lib\site-packages\django\utils\asyncio.py", line 26, in inner
    return func(*args, **kwargs)
           ^^^^^^^^^^^^^^^^^^^^^
  File "C:\Users\genti\OneDrive\Documentos\gestao_eventos\dhenv\Lib\site-packages\django\db\backends\base\base.py", line 256, in connect
    self.connection = self.get_new_connection(conn_params)
                      ^^^^^^^^^^^^^^^^^^^^^^^^^^^^^^^^^^^^
  File "C:\Users\genti\OneDrive\Documentos\gestao_eventos\dhenv\Lib\site-packages\django\utils\asyncio.py", line 26, in inner
    return func(*args, **kwargs)
           ^^^^^^^^^^^^^^^^^^^^^
  File "C:\Users\genti\OneDrive\Documentos\gestao_eventos\dhenv\Lib\site-packages\django\db\backends\postgresql\base.py", line 277, in get_new_connection
    connection = self.Database.connect(**conn_params)
                 ^^^^^^^^^^^^^^^^^^^^^^^^^^^^^^^^^^^^
  File "C:\Users\genti\OneDrive\Documentos\gestao_eventos\dhenv\Lib\site-packages\psycopg\connection.py", line 119, in connect
    raise last_ex.with_traceback(None)
django.db.utils.OperationalError: connection timeout expired
Running job "enviar_mensagens_agendadas (trigger: interval[0:01:00], next run at: 2025-02-05 15:53:28 AEDT)" (scheduled at 2025-02-05 15:52:28.343640+11:00)
Running job "verificar_status (trigger: interval[0:01:00], next run at: 2025-02-05 15:53:28 AEDT)" (scheduled at 2025-02-05 15:52:28.343640+11:00)
Execution of job "enviar_mensagens_agendadas (trigger: interval[0:01:00], next run at: 2025-02-05 15:53:28 AEDT)" skipped: maximum number of running instances reached (1)
Execution of job "verificar_status (trigger: interval[0:01:00], next run at: 2025-02-05 15:53:28 AEDT)" skipped: maximum number of running instances reached (1)
Execution of job "enviar_mensagens_agendadas (trigger: interval[0:01:00], next run at: 2025-02-05 15:54:28 AEDT)" skipped: maximum number of running instances reached (1)
Execution of job "verificar_status (trigger: interval[0:01:00], next run at: 2025-02-05 15:54:28 AEDT)" skipped: maximum number of running instances reached (1)
Job "verificar_status (trigger: interval[0:01:00], next run at: 2025-02-05 15:55:28 AEDT)" raised an exception
Traceback (most recent call last):
  File "C:\Users\genti\OneDrive\Documentos\gestao_eventos\dhenv\Lib\site-packages\django\db\backends\base\base.py", line 275, in ensure_connection
    self.connect()
  File "C:\Users\genti\OneDrive\Documentos\gestao_eventos\dhenv\Lib\site-packages\django\utils\asyncio.py", line 26, in inner
    return func(*args, **kwargs)
           ^^^^^^^^^^^^^^^^^^^^^
  File "C:\Users\genti\OneDrive\Documentos\gestao_eventos\dhenv\Lib\site-packages\django\db\backends\base\base.py", line 256, in connect
    self.connection = self.get_new_connection(conn_params)
                      ^^^^^^^^^^^^^^^^^^^^^^^^^^^^^^^^^^^^
  File "C:\Users\genti\OneDrive\Documentos\gestao_eventos\dhenv\Lib\site-packages\django\utils\asyncio.py", line 26, in inner
    return func(*args, **kwargs)
           ^^^^^^^^^^^^^^^^^^^^^
  File "C:\Users\genti\OneDrive\Documentos\gestao_eventos\dhenv\Lib\site-packages\django\db\backends\postgresql\base.py", line 277, in get_new_connection
    connection = self.Database.connect(**conn_params)
                 ^^^^^^^^^^^^^^^^^^^^^^^^^^^^^^^^^^^^
  File "C:\Users\genti\OneDrive\Documentos\gestao_eventos\dhenv\Lib\site-packages\psycopg\connection.py", line 119, in connect
    raise last_ex.with_traceback(None)
psycopg.errors.ConnectionTimeout: connection timeout expired

The above exception was the direct cause of the following exception:

Traceback (most recent call last):
  File "C:\Users\genti\OneDrive\Documentos\gestao_eventos\dhenv\Lib\site-packages\apscheduler\executors\base.py", line 125, in run_job
    retval = job.func(*job.args, **job.kwargs)
             ^^^^^^^^^^^^^^^^^^^^^^^^^^^^^^^^^
  File "C:\Users\genti\OneDrive\Documentos\gestao_eventos\artistas\tasks.py", line 80, in verificar_status
    for artista in artistas:
  File "C:\Users\genti\OneDrive\Documentos\gestao_eventos\dhenv\Lib\site-packages\django\db\models\query.py", line 400, in __iter__
    self._fetch_all()
  File "C:\Users\genti\OneDrive\Documentos\gestao_eventos\dhenv\Lib\site-packages\django\db\models\query.py", line 1928, in _fetch_all
    self._result_cache = list(self._iterable_class(self))
                         ^^^^^^^^^^^^^^^^^^^^^^^^^^^^^^^^
  File "C:\Users\genti\OneDrive\Documentos\gestao_eventos\dhenv\Lib\site-packages\django\db\models\query.py", line 91, in __iter__
    results = compiler.execute_sql(
              ^^^^^^^^^^^^^^^^^^^^^
  File "C:\Users\genti\OneDrive\Documentos\gestao_eventos\dhenv\Lib\site-packages\django\db\models\sql\compiler.py", line 1560, in execute_sql
    cursor = self.connection.cursor()
             ^^^^^^^^^^^^^^^^^^^^^^^^
  File "C:\Users\genti\OneDrive\Documentos\gestao_eventos\dhenv\Lib\site-packages\django\utils\asyncio.py", line 26, in inner
    return func(*args, **kwargs)
           ^^^^^^^^^^^^^^^^^^^^^
  File "C:\Users\genti\OneDrive\Documentos\gestao_eventos\dhenv\Lib\site-packages\django\db\backends\base\base.py", line 316, in cursor
    return self._cursor()
           ^^^^^^^^^^^^^^
  File "C:\Users\genti\OneDrive\Documentos\gestao_eventos\dhenv\Lib\site-packages\django\db\backends\base\base.py", line 292, in _cursor
    self.ensure_connection()
  File "C:\Users\genti\OneDrive\Documentos\gestao_eventos\dhenv\Lib\site-packages\django\utils\asyncio.py", line 26, in inner
    return func(*args, **kwargs)
           ^^^^^^^^^^^^^^^^^^^^^
  File "C:\Users\genti\OneDrive\Documentos\gestao_eventos\dhenv\Lib\site-packages\django\db\backends\base\base.py", line 274, in ensure_connection
    with self.wrap_database_errors:
  File "C:\Users\genti\OneDrive\Documentos\gestao_eventos\dhenv\Lib\site-packages\django\db\utils.py", line 91, in __exit__
    raise dj_exc_value.with_traceback(traceback) from exc_value
  File "C:\Users\genti\OneDrive\Documentos\gestao_eventos\dhenv\Lib\site-packages\django\db\backends\base\base.py", line 275, in ensure_connection
    self.connect()
  File "C:\Users\genti\OneDrive\Documentos\gestao_eventos\dhenv\Lib\site-packages\django\utils\asyncio.py", line 26, in inner
    return func(*args, **kwargs)
           ^^^^^^^^^^^^^^^^^^^^^
  File "C:\Users\genti\OneDrive\Documentos\gestao_eventos\dhenv\Lib\site-packages\django\db\backends\base\base.py", line 256, in connect
    self.connection = self.get_new_connection(conn_params)
                      ^^^^^^^^^^^^^^^^^^^^^^^^^^^^^^^^^^^^
  File "C:\Users\genti\OneDrive\Documentos\gestao_eventos\dhenv\Lib\site-packages\django\utils\asyncio.py", line 26, in inner
    return func(*args, **kwargs)
           ^^^^^^^^^^^^^^^^^^^^^
  File "C:\Users\genti\OneDrive\Documentos\gestao_eventos\dhenv\Lib\site-packages\django\db\backends\postgresql\base.py", line 277, in get_new_connection
    connection = self.Database.connect(**conn_params)
                 ^^^^^^^^^^^^^^^^^^^^^^^^^^^^^^^^^^^^
  File "C:\Users\genti\OneDrive\Documentos\gestao_eventos\dhenv\Lib\site-packages\psycopg\connection.py", line 119, in connect
    raise last_ex.with_traceback(None)
django.db.utils.OperationalError: connection timeout expired
Job "enviar_mensagens_agendadas (trigger: interval[0:01:00], next run at: 2025-02-05 15:55:28 AEDT)" raised an exception
Traceback (most recent call last):
  File "C:\Users\genti\OneDrive\Documentos\gestao_eventos\dhenv\Lib\site-packages\django\db\backends\base\base.py", line 275, in ensure_connection
    self.connect()
  File "C:\Users\genti\OneDrive\Documentos\gestao_eventos\dhenv\Lib\site-packages\django\utils\asyncio.py", line 26, in inner
    return func(*args, **kwargs)
           ^^^^^^^^^^^^^^^^^^^^^
  File "C:\Users\genti\OneDrive\Documentos\gestao_eventos\dhenv\Lib\site-packages\django\db\backends\base\base.py", line 256, in connect
    self.connection = self.get_new_connection(conn_params)
                      ^^^^^^^^^^^^^^^^^^^^^^^^^^^^^^^^^^^^
  File "C:\Users\genti\OneDrive\Documentos\gestao_eventos\dhenv\Lib\site-packages\django\utils\asyncio.py", line 26, in inner
    return func(*args, **kwargs)
           ^^^^^^^^^^^^^^^^^^^^^
  File "C:\Users\genti\OneDrive\Documentos\gestao_eventos\dhenv\Lib\site-packages\django\db\backends\postgresql\base.py", line 277, in get_new_connection
    connection = self.Database.connect(**conn_params)
                 ^^^^^^^^^^^^^^^^^^^^^^^^^^^^^^^^^^^^
  File "C:\Users\genti\OneDrive\Documentos\gestao_eventos\dhenv\Lib\site-packages\psycopg\connection.py", line 119, in connect
    raise last_ex.with_traceback(None)
psycopg.errors.ConnectionTimeout: connection timeout expired

The above exception was the direct cause of the following exception:

Traceback (most recent call last):
  File "C:\Users\genti\OneDrive\Documentos\gestao_eventos\dhenv\Lib\site-packages\apscheduler\executors\base.py", line 125, in run_job
    retval = job.func(*job.args, **job.kwargs)
             ^^^^^^^^^^^^^^^^^^^^^^^^^^^^^^^^^
  File "C:\Users\genti\OneDrive\Documentos\gestao_eventos\artistas\tasks.py", line 43, in enviar_mensagens_agendadas
    for artista in artistas:
  File "C:\Users\genti\OneDrive\Documentos\gestao_eventos\dhenv\Lib\site-packages\django\db\models\query.py", line 400, in __iter__
    self._fetch_all()
  File "C:\Users\genti\OneDrive\Documentos\gestao_eventos\dhenv\Lib\site-packages\django\db\models\query.py", line 1928, in _fetch_all
    self._result_cache = list(self._iterable_class(self))
                         ^^^^^^^^^^^^^^^^^^^^^^^^^^^^^^^^
  File "C:\Users\genti\OneDrive\Documentos\gestao_eventos\dhenv\Lib\site-packages\django\db\models\query.py", line 91, in __iter__
    results = compiler.execute_sql(
              ^^^^^^^^^^^^^^^^^^^^^
  File "C:\Users\genti\OneDrive\Documentos\gestao_eventos\dhenv\Lib\site-packages\django\db\models\sql\compiler.py", line 1560, in execute_sql
    cursor = self.connection.cursor()
             ^^^^^^^^^^^^^^^^^^^^^^^^
  File "C:\Users\genti\OneDrive\Documentos\gestao_eventos\dhenv\Lib\site-packages\django\utils\asyncio.py", line 26, in inner
    return func(*args, **kwargs)
           ^^^^^^^^^^^^^^^^^^^^^
  File "C:\Users\genti\OneDrive\Documentos\gestao_eventos\dhenv\Lib\site-packages\django\db\backends\base\base.py", line 316, in cursor
    return self._cursor()
           ^^^^^^^^^^^^^^
  File "C:\Users\genti\OneDrive\Documentos\gestao_eventos\dhenv\Lib\site-packages\django\db\backends\base\base.py", line 292, in _cursor
    self.ensure_connection()
  File "C:\Users\genti\OneDrive\Documentos\gestao_eventos\dhenv\Lib\site-packages\django\utils\asyncio.py", line 26, in inner
    return func(*args, **kwargs)
           ^^^^^^^^^^^^^^^^^^^^^
  File "C:\Users\genti\OneDrive\Documentos\gestao_eventos\dhenv\Lib\site-packages\django\db\backends\base\base.py", line 274, in ensure_connection
    with self.wrap_database_errors:
  File "C:\Users\genti\OneDrive\Documentos\gestao_eventos\dhenv\Lib\site-packages\django\db\utils.py", line 91, in __exit__
    raise dj_exc_value.with_traceback(traceback) from exc_value
  File "C:\Users\genti\OneDrive\Documentos\gestao_eventos\dhenv\Lib\site-packages\django\db\backends\base\base.py", line 275, in ensure_connection
    self.connect()
  File "C:\Users\genti\OneDrive\Documentos\gestao_eventos\dhenv\Lib\site-packages\django\utils\asyncio.py", line 26, in inner
    return func(*args, **kwargs)
           ^^^^^^^^^^^^^^^^^^^^^
  File "C:\Users\genti\OneDrive\Documentos\gestao_eventos\dhenv\Lib\site-packages\django\db\backends\base\base.py", line 256, in connect
    self.connection = self.get_new_connection(conn_params)
                      ^^^^^^^^^^^^^^^^^^^^^^^^^^^^^^^^^^^^
  File "C:\Users\genti\OneDrive\Documentos\gestao_eventos\dhenv\Lib\site-packages\django\utils\asyncio.py", line 26, in inner
    return func(*args, **kwargs)
           ^^^^^^^^^^^^^^^^^^^^^
  File "C:\Users\genti\OneDrive\Documentos\gestao_eventos\dhenv\Lib\site-packages\django\db\backends\postgresql\base.py", line 277, in get_new_connection
    connection = self.Database.connect(**conn_params)
                 ^^^^^^^^^^^^^^^^^^^^^^^^^^^^^^^^^^^^
  File "C:\Users\genti\OneDrive\Documentos\gestao_eventos\dhenv\Lib\site-packages\psycopg\connection.py", line 119, in connect
    raise last_ex.with_traceback(None)
django.db.utils.OperationalError: connection timeout expired
Scheduler started
Running job "enviar_mensagens_agendadas (trigger: interval[0:01:00], next run at: 2025-02-05 16:19:05 AEDT)" (scheduled at 2025-02-05 16:18:05.822915+11:00)
Running job "verificar_status (trigger: interval[0:01:00], next run at: 2025-02-05 16:19:05 AEDT)" (scheduled at 2025-02-05 16:18:05.823919+11:00)
Job "verificar_status (trigger: interval[0:01:00], next run at: 2025-02-05 16:19:05 AEDT)" raised an exception
Traceback (most recent call last):
  File "C:\Users\genti\OneDrive\Documentos\gestao_eventos\dhenv\Lib\site-packages\django\db\backends\base\base.py", line 275, in ensure_connection
    self.connect()
  File "C:\Users\genti\OneDrive\Documentos\gestao_eventos\dhenv\Lib\site-packages\django\utils\asyncio.py", line 26, in inner
    return func(*args, **kwargs)
           ^^^^^^^^^^^^^^^^^^^^^
  File "C:\Users\genti\OneDrive\Documentos\gestao_eventos\dhenv\Lib\site-packages\django\db\backends\base\base.py", line 256, in connect
    self.connection = self.get_new_connection(conn_params)
                      ^^^^^^^^^^^^^^^^^^^^^^^^^^^^^^^^^^^^
  File "C:\Users\genti\OneDrive\Documentos\gestao_eventos\dhenv\Lib\site-packages\django\utils\asyncio.py", line 26, in inner
    return func(*args, **kwargs)
           ^^^^^^^^^^^^^^^^^^^^^
  File "C:\Users\genti\OneDrive\Documentos\gestao_eventos\dhenv\Lib\site-packages\django\db\backends\postgresql\base.py", line 277, in get_new_connection
    connection = self.Database.connect(**conn_params)
                 ^^^^^^^^^^^^^^^^^^^^^^^^^^^^^^^^^^^^
  File "C:\Users\genti\OneDrive\Documentos\gestao_eventos\dhenv\Lib\site-packages\psycopg\connection.py", line 98, in connect
    attempts = conninfo_attempts(params)
               ^^^^^^^^^^^^^^^^^^^^^^^^^
  File "C:\Users\genti\OneDrive\Documentos\gestao_eventos\dhenv\Lib\site-packages\psycopg\_conninfo_attempts.py", line 50, in conninfo_attempts
    raise e.OperationalError(str(last_exc))
psycopg.OperationalError: [Errno 11001] getaddrinfo failed

The above exception was the direct cause of the following exception:

Traceback (most recent call last):
  File "C:\Users\genti\OneDrive\Documentos\gestao_eventos\dhenv\Lib\site-packages\apscheduler\executors\base.py", line 125, in run_job
    retval = job.func(*job.args, **job.kwargs)
             ^^^^^^^^^^^^^^^^^^^^^^^^^^^^^^^^^
  File "C:\Users\genti\OneDrive\Documentos\gestao_eventos\artistas\tasks.py", line 80, in verificar_status
    for artista in artistas:
  File "C:\Users\genti\OneDrive\Documentos\gestao_eventos\dhenv\Lib\site-packages\django\db\models\query.py", line 400, in __iter__
    self._fetch_all()
  File "C:\Users\genti\OneDrive\Documentos\gestao_eventos\dhenv\Lib\site-packages\django\db\models\query.py", line 1928, in _fetch_all
    self._result_cache = list(self._iterable_class(self))
                         ^^^^^^^^^^^^^^^^^^^^^^^^^^^^^^^^
  File "C:\Users\genti\OneDrive\Documentos\gestao_eventos\dhenv\Lib\site-packages\django\db\models\query.py", line 91, in __iter__
    results = compiler.execute_sql(
              ^^^^^^^^^^^^^^^^^^^^^
  File "C:\Users\genti\OneDrive\Documentos\gestao_eventos\dhenv\Lib\site-packages\django\db\models\sql\compiler.py", line 1560, in execute_sql
    cursor = self.connection.cursor()
             ^^^^^^^^^^^^^^^^^^^^^^^^
  File "C:\Users\genti\OneDrive\Documentos\gestao_eventos\dhenv\Lib\site-packages\django\utils\asyncio.py", line 26, in inner
    return func(*args, **kwargs)
           ^^^^^^^^^^^^^^^^^^^^^
  File "C:\Users\genti\OneDrive\Documentos\gestao_eventos\dhenv\Lib\site-packages\django\db\backends\base\base.py", line 316, in cursor
    return self._cursor()
           ^^^^^^^^^^^^^^
  File "C:\Users\genti\OneDrive\Documentos\gestao_eventos\dhenv\Lib\site-packages\django\db\backends\base\base.py", line 292, in _cursor
    self.ensure_connection()
  File "C:\Users\genti\OneDrive\Documentos\gestao_eventos\dhenv\Lib\site-packages\django\utils\asyncio.py", line 26, in inner
    return func(*args, **kwargs)
           ^^^^^^^^^^^^^^^^^^^^^
  File "C:\Users\genti\OneDrive\Documentos\gestao_eventos\dhenv\Lib\site-packages\django\db\backends\base\base.py", line 274, in ensure_connection
    with self.wrap_database_errors:
  File "C:\Users\genti\OneDrive\Documentos\gestao_eventos\dhenv\Lib\site-packages\django\db\utils.py", line 91, in __exit__
    raise dj_exc_value.with_traceback(traceback) from exc_value
  File "C:\Users\genti\OneDrive\Documentos\gestao_eventos\dhenv\Lib\site-packages\django\db\backends\base\base.py", line 275, in ensure_connection
    self.connect()
  File "C:\Users\genti\OneDrive\Documentos\gestao_eventos\dhenv\Lib\site-packages\django\utils\asyncio.py", line 26, in inner
    return func(*args, **kwargs)
           ^^^^^^^^^^^^^^^^^^^^^
  File "C:\Users\genti\OneDrive\Documentos\gestao_eventos\dhenv\Lib\site-packages\django\db\backends\base\base.py", line 256, in connect
    self.connection = self.get_new_connection(conn_params)
                      ^^^^^^^^^^^^^^^^^^^^^^^^^^^^^^^^^^^^
  File "C:\Users\genti\OneDrive\Documentos\gestao_eventos\dhenv\Lib\site-packages\django\utils\asyncio.py", line 26, in inner
    return func(*args, **kwargs)
           ^^^^^^^^^^^^^^^^^^^^^
  File "C:\Users\genti\OneDrive\Documentos\gestao_eventos\dhenv\Lib\site-packages\django\db\backends\postgresql\base.py", line 277, in get_new_connection
    connection = self.Database.connect(**conn_params)
                 ^^^^^^^^^^^^^^^^^^^^^^^^^^^^^^^^^^^^
  File "C:\Users\genti\OneDrive\Documentos\gestao_eventos\dhenv\Lib\site-packages\psycopg\connection.py", line 98, in connect
    attempts = conninfo_attempts(params)
               ^^^^^^^^^^^^^^^^^^^^^^^^^
  File "C:\Users\genti\OneDrive\Documentos\gestao_eventos\dhenv\Lib\site-packages\psycopg\_conninfo_attempts.py", line 50, in conninfo_attempts
    raise e.OperationalError(str(last_exc))
django.db.utils.OperationalError: [Errno 11001] getaddrinfo failed
Job "enviar_mensagens_agendadas (trigger: interval[0:01:00], next run at: 2025-02-05 16:19:05 AEDT)" raised an exception
Traceback (most recent call last):
  File "C:\Users\genti\OneDrive\Documentos\gestao_eventos\dhenv\Lib\site-packages\django\db\backends\base\base.py", line 275, in ensure_connection
    self.connect()
  File "C:\Users\genti\OneDrive\Documentos\gestao_eventos\dhenv\Lib\site-packages\django\utils\asyncio.py", line 26, in inner
    return func(*args, **kwargs)
           ^^^^^^^^^^^^^^^^^^^^^
  File "C:\Users\genti\OneDrive\Documentos\gestao_eventos\dhenv\Lib\site-packages\django\db\backends\base\base.py", line 256, in connect
    self.connection = self.get_new_connection(conn_params)
                      ^^^^^^^^^^^^^^^^^^^^^^^^^^^^^^^^^^^^
  File "C:\Users\genti\OneDrive\Documentos\gestao_eventos\dhenv\Lib\site-packages\django\utils\asyncio.py", line 26, in inner
    return func(*args, **kwargs)
           ^^^^^^^^^^^^^^^^^^^^^
  File "C:\Users\genti\OneDrive\Documentos\gestao_eventos\dhenv\Lib\site-packages\django\db\backends\postgresql\base.py", line 277, in get_new_connection
    connection = self.Database.connect(**conn_params)
                 ^^^^^^^^^^^^^^^^^^^^^^^^^^^^^^^^^^^^
  File "C:\Users\genti\OneDrive\Documentos\gestao_eventos\dhenv\Lib\site-packages\psycopg\connection.py", line 98, in connect
    attempts = conninfo_attempts(params)
               ^^^^^^^^^^^^^^^^^^^^^^^^^
  File "C:\Users\genti\OneDrive\Documentos\gestao_eventos\dhenv\Lib\site-packages\psycopg\_conninfo_attempts.py", line 50, in conninfo_attempts
    raise e.OperationalError(str(last_exc))
psycopg.OperationalError: [Errno 11001] getaddrinfo failed

The above exception was the direct cause of the following exception:

Traceback (most recent call last):
  File "C:\Users\genti\OneDrive\Documentos\gestao_eventos\dhenv\Lib\site-packages\apscheduler\executors\base.py", line 125, in run_job
    retval = job.func(*job.args, **job.kwargs)
             ^^^^^^^^^^^^^^^^^^^^^^^^^^^^^^^^^
  File "C:\Users\genti\OneDrive\Documentos\gestao_eventos\artistas\tasks.py", line 43, in enviar_mensagens_agendadas
    for artista in artistas:
  File "C:\Users\genti\OneDrive\Documentos\gestao_eventos\dhenv\Lib\site-packages\django\db\models\query.py", line 400, in __iter__
    self._fetch_all()
  File "C:\Users\genti\OneDrive\Documentos\gestao_eventos\dhenv\Lib\site-packages\django\db\models\query.py", line 1928, in _fetch_all
    self._result_cache = list(self._iterable_class(self))
                         ^^^^^^^^^^^^^^^^^^^^^^^^^^^^^^^^
  File "C:\Users\genti\OneDrive\Documentos\gestao_eventos\dhenv\Lib\site-packages\django\db\models\query.py", line 91, in __iter__
    results = compiler.execute_sql(
              ^^^^^^^^^^^^^^^^^^^^^
  File "C:\Users\genti\OneDrive\Documentos\gestao_eventos\dhenv\Lib\site-packages\django\db\models\sql\compiler.py", line 1560, in execute_sql
    cursor = self.connection.cursor()
             ^^^^^^^^^^^^^^^^^^^^^^^^
  File "C:\Users\genti\OneDrive\Documentos\gestao_eventos\dhenv\Lib\site-packages\django\utils\asyncio.py", line 26, in inner
    return func(*args, **kwargs)
           ^^^^^^^^^^^^^^^^^^^^^
  File "C:\Users\genti\OneDrive\Documentos\gestao_eventos\dhenv\Lib\site-packages\django\db\backends\base\base.py", line 316, in cursor
    return self._cursor()
           ^^^^^^^^^^^^^^
  File "C:\Users\genti\OneDrive\Documentos\gestao_eventos\dhenv\Lib\site-packages\django\db\backends\base\base.py", line 292, in _cursor
    self.ensure_connection()
  File "C:\Users\genti\OneDrive\Documentos\gestao_eventos\dhenv\Lib\site-packages\django\utils\asyncio.py", line 26, in inner
    return func(*args, **kwargs)
           ^^^^^^^^^^^^^^^^^^^^^
  File "C:\Users\genti\OneDrive\Documentos\gestao_eventos\dhenv\Lib\site-packages\django\db\backends\base\base.py", line 274, in ensure_connection
    with self.wrap_database_errors:
  File "C:\Users\genti\OneDrive\Documentos\gestao_eventos\dhenv\Lib\site-packages\django\db\utils.py", line 91, in __exit__
    raise dj_exc_value.with_traceback(traceback) from exc_value
  File "C:\Users\genti\OneDrive\Documentos\gestao_eventos\dhenv\Lib\site-packages\django\db\backends\base\base.py", line 275, in ensure_connection
    self.connect()
  File "C:\Users\genti\OneDrive\Documentos\gestao_eventos\dhenv\Lib\site-packages\django\utils\asyncio.py", line 26, in inner
    return func(*args, **kwargs)
           ^^^^^^^^^^^^^^^^^^^^^
  File "C:\Users\genti\OneDrive\Documentos\gestao_eventos\dhenv\Lib\site-packages\django\db\backends\base\base.py", line 256, in connect
    self.connection = self.get_new_connection(conn_params)
                      ^^^^^^^^^^^^^^^^^^^^^^^^^^^^^^^^^^^^
  File "C:\Users\genti\OneDrive\Documentos\gestao_eventos\dhenv\Lib\site-packages\django\utils\asyncio.py", line 26, in inner
    return func(*args, **kwargs)
           ^^^^^^^^^^^^^^^^^^^^^
  File "C:\Users\genti\OneDrive\Documentos\gestao_eventos\dhenv\Lib\site-packages\django\db\backends\postgresql\base.py", line 277, in get_new_connection
    connection = self.Database.connect(**conn_params)
                 ^^^^^^^^^^^^^^^^^^^^^^^^^^^^^^^^^^^^
  File "C:\Users\genti\OneDrive\Documentos\gestao_eventos\dhenv\Lib\site-packages\psycopg\connection.py", line 98, in connect
    attempts = conninfo_attempts(params)
               ^^^^^^^^^^^^^^^^^^^^^^^^^
  File "C:\Users\genti\OneDrive\Documentos\gestao_eventos\dhenv\Lib\site-packages\psycopg\_conninfo_attempts.py", line 50, in conninfo_attempts
    raise e.OperationalError(str(last_exc))
django.db.utils.OperationalError: [Errno 11001] getaddrinfo failed
Running job "enviar_mensagens_agendadas (trigger: interval[0:01:00], next run at: 2025-02-05 16:20:05 AEDT)" (scheduled at 2025-02-05 16:19:05.822915+11:00)
Running job "verificar_status (trigger: interval[0:01:00], next run at: 2025-02-05 16:20:05 AEDT)" (scheduled at 2025-02-05 16:19:05.823919+11:00)
Job "enviar_mensagens_agendadas (trigger: interval[0:01:00], next run at: 2025-02-05 16:20:05 AEDT)" raised an exception
Traceback (most recent call last):
  File "C:\Users\genti\OneDrive\Documentos\gestao_eventos\dhenv\Lib\site-packages\django\db\backends\base\base.py", line 275, in ensure_connection
    self.connect()
  File "C:\Users\genti\OneDrive\Documentos\gestao_eventos\dhenv\Lib\site-packages\django\utils\asyncio.py", line 26, in inner
    return func(*args, **kwargs)
           ^^^^^^^^^^^^^^^^^^^^^
  File "C:\Users\genti\OneDrive\Documentos\gestao_eventos\dhenv\Lib\site-packages\django\db\backends\base\base.py", line 256, in connect
    self.connection = self.get_new_connection(conn_params)
                      ^^^^^^^^^^^^^^^^^^^^^^^^^^^^^^^^^^^^
  File "C:\Users\genti\OneDrive\Documentos\gestao_eventos\dhenv\Lib\site-packages\django\utils\asyncio.py", line 26, in inner
    return func(*args, **kwargs)
           ^^^^^^^^^^^^^^^^^^^^^
  File "C:\Users\genti\OneDrive\Documentos\gestao_eventos\dhenv\Lib\site-packages\django\db\backends\postgresql\base.py", line 277, in get_new_connection
    connection = self.Database.connect(**conn_params)
                 ^^^^^^^^^^^^^^^^^^^^^^^^^^^^^^^^^^^^
  File "C:\Users\genti\OneDrive\Documentos\gestao_eventos\dhenv\Lib\site-packages\psycopg\connection.py", line 98, in connect
    attempts = conninfo_attempts(params)
               ^^^^^^^^^^^^^^^^^^^^^^^^^
  File "C:\Users\genti\OneDrive\Documentos\gestao_eventos\dhenv\Lib\site-packages\psycopg\_conninfo_attempts.py", line 50, in conninfo_attempts
    raise e.OperationalError(str(last_exc))
psycopg.OperationalError: [Errno 11001] getaddrinfo failed

The above exception was the direct cause of the following exception:

Traceback (most recent call last):
  File "C:\Users\genti\OneDrive\Documentos\gestao_eventos\dhenv\Lib\site-packages\apscheduler\executors\base.py", line 125, in run_job
    retval = job.func(*job.args, **job.kwargs)
             ^^^^^^^^^^^^^^^^^^^^^^^^^^^^^^^^^
  File "C:\Users\genti\OneDrive\Documentos\gestao_eventos\artistas\tasks.py", line 43, in enviar_mensagens_agendadas
    for artista in artistas:
  File "C:\Users\genti\OneDrive\Documentos\gestao_eventos\dhenv\Lib\site-packages\django\db\models\query.py", line 400, in __iter__
    self._fetch_all()
  File "C:\Users\genti\OneDrive\Documentos\gestao_eventos\dhenv\Lib\site-packages\django\db\models\query.py", line 1928, in _fetch_all
    self._result_cache = list(self._iterable_class(self))
                         ^^^^^^^^^^^^^^^^^^^^^^^^^^^^^^^^
  File "C:\Users\genti\OneDrive\Documentos\gestao_eventos\dhenv\Lib\site-packages\django\db\models\query.py", line 91, in __iter__
    results = compiler.execute_sql(
              ^^^^^^^^^^^^^^^^^^^^^
  File "C:\Users\genti\OneDrive\Documentos\gestao_eventos\dhenv\Lib\site-packages\django\db\models\sql\compiler.py", line 1560, in execute_sql
    cursor = self.connection.cursor()
             ^^^^^^^^^^^^^^^^^^^^^^^^
  File "C:\Users\genti\OneDrive\Documentos\gestao_eventos\dhenv\Lib\site-packages\django\utils\asyncio.py", line 26, in inner
    return func(*args, **kwargs)
           ^^^^^^^^^^^^^^^^^^^^^
  File "C:\Users\genti\OneDrive\Documentos\gestao_eventos\dhenv\Lib\site-packages\django\db\backends\base\base.py", line 316, in cursor
    return self._cursor()
           ^^^^^^^^^^^^^^
  File "C:\Users\genti\OneDrive\Documentos\gestao_eventos\dhenv\Lib\site-packages\django\db\backends\base\base.py", line 292, in _cursor
    self.ensure_connection()
  File "C:\Users\genti\OneDrive\Documentos\gestao_eventos\dhenv\Lib\site-packages\django\utils\asyncio.py", line 26, in inner
    return func(*args, **kwargs)
           ^^^^^^^^^^^^^^^^^^^^^
  File "C:\Users\genti\OneDrive\Documentos\gestao_eventos\dhenv\Lib\site-packages\django\db\backends\base\base.py", line 274, in ensure_connection
    with self.wrap_database_errors:
  File "C:\Users\genti\OneDrive\Documentos\gestao_eventos\dhenv\Lib\site-packages\django\db\utils.py", line 91, in __exit__
    raise dj_exc_value.with_traceback(traceback) from exc_value
  File "C:\Users\genti\OneDrive\Documentos\gestao_eventos\dhenv\Lib\site-packages\django\db\backends\base\base.py", line 275, in ensure_connection
    self.connect()
  File "C:\Users\genti\OneDrive\Documentos\gestao_eventos\dhenv\Lib\site-packages\django\utils\asyncio.py", line 26, in inner
    return func(*args, **kwargs)
           ^^^^^^^^^^^^^^^^^^^^^
  File "C:\Users\genti\OneDrive\Documentos\gestao_eventos\dhenv\Lib\site-packages\django\db\backends\base\base.py", line 256, in connect
    self.connection = self.get_new_connection(conn_params)
                      ^^^^^^^^^^^^^^^^^^^^^^^^^^^^^^^^^^^^
  File "C:\Users\genti\OneDrive\Documentos\gestao_eventos\dhenv\Lib\site-packages\django\utils\asyncio.py", line 26, in inner
    return func(*args, **kwargs)
           ^^^^^^^^^^^^^^^^^^^^^
  File "C:\Users\genti\OneDrive\Documentos\gestao_eventos\dhenv\Lib\site-packages\django\db\backends\postgresql\base.py", line 277, in get_new_connection
    connection = self.Database.connect(**conn_params)
                 ^^^^^^^^^^^^^^^^^^^^^^^^^^^^^^^^^^^^
  File "C:\Users\genti\OneDrive\Documentos\gestao_eventos\dhenv\Lib\site-packages\psycopg\connection.py", line 98, in connect
    attempts = conninfo_attempts(params)
               ^^^^^^^^^^^^^^^^^^^^^^^^^
  File "C:\Users\genti\OneDrive\Documentos\gestao_eventos\dhenv\Lib\site-packages\psycopg\_conninfo_attempts.py", line 50, in conninfo_attempts
    raise e.OperationalError(str(last_exc))
django.db.utils.OperationalError: [Errno 11001] getaddrinfo failed
Job "verificar_status (trigger: interval[0:01:00], next run at: 2025-02-05 16:20:05 AEDT)" raised an exception
Traceback (most recent call last):
  File "C:\Users\genti\OneDrive\Documentos\gestao_eventos\dhenv\Lib\site-packages\django\db\backends\base\base.py", line 275, in ensure_connection
    self.connect()
  File "C:\Users\genti\OneDrive\Documentos\gestao_eventos\dhenv\Lib\site-packages\django\utils\asyncio.py", line 26, in inner
    return func(*args, **kwargs)
           ^^^^^^^^^^^^^^^^^^^^^
  File "C:\Users\genti\OneDrive\Documentos\gestao_eventos\dhenv\Lib\site-packages\django\db\backends\base\base.py", line 256, in connect
    self.connection = self.get_new_connection(conn_params)
                      ^^^^^^^^^^^^^^^^^^^^^^^^^^^^^^^^^^^^
  File "C:\Users\genti\OneDrive\Documentos\gestao_eventos\dhenv\Lib\site-packages\django\utils\asyncio.py", line 26, in inner
    return func(*args, **kwargs)
           ^^^^^^^^^^^^^^^^^^^^^
  File "C:\Users\genti\OneDrive\Documentos\gestao_eventos\dhenv\Lib\site-packages\django\db\backends\postgresql\base.py", line 277, in get_new_connection
    connection = self.Database.connect(**conn_params)
                 ^^^^^^^^^^^^^^^^^^^^^^^^^^^^^^^^^^^^
  File "C:\Users\genti\OneDrive\Documentos\gestao_eventos\dhenv\Lib\site-packages\psycopg\connection.py", line 98, in connect
    attempts = conninfo_attempts(params)
               ^^^^^^^^^^^^^^^^^^^^^^^^^
  File "C:\Users\genti\OneDrive\Documentos\gestao_eventos\dhenv\Lib\site-packages\psycopg\_conninfo_attempts.py", line 50, in conninfo_attempts
    raise e.OperationalError(str(last_exc))
psycopg.OperationalError: [Errno 11001] getaddrinfo failed

The above exception was the direct cause of the following exception:

Traceback (most recent call last):
  File "C:\Users\genti\OneDrive\Documentos\gestao_eventos\dhenv\Lib\site-packages\apscheduler\executors\base.py", line 125, in run_job
    retval = job.func(*job.args, **job.kwargs)
             ^^^^^^^^^^^^^^^^^^^^^^^^^^^^^^^^^
  File "C:\Users\genti\OneDrive\Documentos\gestao_eventos\artistas\tasks.py", line 80, in verificar_status
    for artista in artistas:
  File "C:\Users\genti\OneDrive\Documentos\gestao_eventos\dhenv\Lib\site-packages\django\db\models\query.py", line 400, in __iter__
    self._fetch_all()
  File "C:\Users\genti\OneDrive\Documentos\gestao_eventos\dhenv\Lib\site-packages\django\db\models\query.py", line 1928, in _fetch_all
    self._result_cache = list(self._iterable_class(self))
                         ^^^^^^^^^^^^^^^^^^^^^^^^^^^^^^^^
  File "C:\Users\genti\OneDrive\Documentos\gestao_eventos\dhenv\Lib\site-packages\django\db\models\query.py", line 91, in __iter__
    results = compiler.execute_sql(
              ^^^^^^^^^^^^^^^^^^^^^
  File "C:\Users\genti\OneDrive\Documentos\gestao_eventos\dhenv\Lib\site-packages\django\db\models\sql\compiler.py", line 1560, in execute_sql
    cursor = self.connection.cursor()
             ^^^^^^^^^^^^^^^^^^^^^^^^
  File "C:\Users\genti\OneDrive\Documentos\gestao_eventos\dhenv\Lib\site-packages\django\utils\asyncio.py", line 26, in inner
    return func(*args, **kwargs)
           ^^^^^^^^^^^^^^^^^^^^^
  File "C:\Users\genti\OneDrive\Documentos\gestao_eventos\dhenv\Lib\site-packages\django\db\backends\base\base.py", line 316, in cursor
    return self._cursor()
           ^^^^^^^^^^^^^^
  File "C:\Users\genti\OneDrive\Documentos\gestao_eventos\dhenv\Lib\site-packages\django\db\backends\base\base.py", line 292, in _cursor
    self.ensure_connection()
  File "C:\Users\genti\OneDrive\Documentos\gestao_eventos\dhenv\Lib\site-packages\django\utils\asyncio.py", line 26, in inner
    return func(*args, **kwargs)
           ^^^^^^^^^^^^^^^^^^^^^
  File "C:\Users\genti\OneDrive\Documentos\gestao_eventos\dhenv\Lib\site-packages\django\db\backends\base\base.py", line 274, in ensure_connection
    with self.wrap_database_errors:
  File "C:\Users\genti\OneDrive\Documentos\gestao_eventos\dhenv\Lib\site-packages\django\db\utils.py", line 91, in __exit__
    raise dj_exc_value.with_traceback(traceback) from exc_value
  File "C:\Users\genti\OneDrive\Documentos\gestao_eventos\dhenv\Lib\site-packages\django\db\backends\base\base.py", line 275, in ensure_connection
    self.connect()
  File "C:\Users\genti\OneDrive\Documentos\gestao_eventos\dhenv\Lib\site-packages\django\utils\asyncio.py", line 26, in inner
    return func(*args, **kwargs)
           ^^^^^^^^^^^^^^^^^^^^^
  File "C:\Users\genti\OneDrive\Documentos\gestao_eventos\dhenv\Lib\site-packages\django\db\backends\base\base.py", line 256, in connect
    self.connection = self.get_new_connection(conn_params)
                      ^^^^^^^^^^^^^^^^^^^^^^^^^^^^^^^^^^^^
  File "C:\Users\genti\OneDrive\Documentos\gestao_eventos\dhenv\Lib\site-packages\django\utils\asyncio.py", line 26, in inner
    return func(*args, **kwargs)
           ^^^^^^^^^^^^^^^^^^^^^
  File "C:\Users\genti\OneDrive\Documentos\gestao_eventos\dhenv\Lib\site-packages\django\db\backends\postgresql\base.py", line 277, in get_new_connection
    connection = self.Database.connect(**conn_params)
                 ^^^^^^^^^^^^^^^^^^^^^^^^^^^^^^^^^^^^
  File "C:\Users\genti\OneDrive\Documentos\gestao_eventos\dhenv\Lib\site-packages\psycopg\connection.py", line 98, in connect
    attempts = conninfo_attempts(params)
               ^^^^^^^^^^^^^^^^^^^^^^^^^
  File "C:\Users\genti\OneDrive\Documentos\gestao_eventos\dhenv\Lib\site-packages\psycopg\_conninfo_attempts.py", line 50, in conninfo_attempts
    raise e.OperationalError(str(last_exc))
django.db.utils.OperationalError: [Errno 11001] getaddrinfo failed
